<?xml version="1.0" encoding="utf-8"?>
<!-- This URDF was automatically created by SolidWorks to URDF Exporter! Originally created by Stephen Brawner (brawner@gmail.com) 
     Commit Version: 1.6.0-4-g7f85cfe  Build Version: 1.6.7995.38578
     For more information, please see http://wiki.ros.org/sw_urdf_exporter -->
<robot
  name="DAS_Controller_V3">
  <link
    name="base_link">
    <inertial>
      <origin
        xyz="-0.0098968745863786 0.000623570740534318 -0.0640173800419082"
        rpy="0 0 0" />
      <mass
        value="0.163845229986071" />
      <inertia
        ixx="0.000191560075935586"
        ixy="-6.78422186811807E-08"
        ixz="-1.92962525145692E-05"
        iyy="0.000108661731991947"
        iyz="1.81634830565732E-07"
        izz="0.000173585447923649" />
    </inertial>
    <visual>
      <origin
        xyz="0 0 0"
        rpy="0 0 0" />
      <geometry>
        <mesh
          filename="meshes/base_link.STL" />
      </geometry>
      <material
        name="">
        <color
          rgba="1 1 1 1" />
      </material>
    </visual>
    <collision>
      <origin
        xyz="0 0 0"
        rpy="0 0 0" />
      <geometry>
        <mesh
          filename="meshes/base_link.STL" />
      </geometry>
    </collision>
  </link>
  <link
    name="link1">
    <inertial>
      <origin
        xyz="0.011501 0.013706 -0.0086124"
        rpy="0 0 0" />
      <mass
        value="0.020935" />
      <inertia
        ixx="6.7399E-06"
        ixy="-3.9584E-06"
        ixz="2.0149E-07"
        iyy="5.2567E-06"
        iyz="3.1396E-07"
        izz="1.151E-05" />
    </inertial>
    <visual>
      <origin
        xyz="0 0 0"
        rpy="0 0 0" />
      <geometry>
        <mesh
          filename="meshes/link1.STL" />
      </geometry>
      <material
        name="">
        <color
          rgba="1 1 0.8 1" />
      </material>
    </visual>
    <collision>
      <origin
        xyz="0 0 0"
        rpy="0 0 0" />
      <geometry>
        <mesh
          filename="meshes/link1.STL" />
      </geometry>
    </collision>
  </link>
  <joint
    name="joint1"
    type="revolute">
    <origin
      xyz="0.022278 0.043372 -0.059518"
      rpy="0 -0.2618 0" />
    <parent
      link="base_link" />
    <child
      link="link1" />
    <axis
      xyz="0 0 -1" />
    <limit
      lower="0"
      upper="0.925"
      effort="100"
      velocity="1" />
  </joint>
  <link
    name="link3">
    <inertial>
      <origin
        xyz="0.028197 -0.027845 -0.0093862"
        rpy="0 0 0" />
      <mass
        value="0.020324" />
      <inertia
        ixx="8.4429E-07"
        ixy="4.187E-07"
        ixz="2.1504E-12"
        iyy="4.9096E-06"
        iyz="2.5086E-14"
        izz="4.8889E-06" />
    </inertial>
    <visual>
      <origin
        xyz="0 0 0"
        rpy="0 0 0" />
      <geometry>
        <mesh
          filename="meshes/link3.STL" />
      </geometry>
      <material
        name="">
        <color
          rgba="0.49804 0.49804 0.49804 1" />
      </material>
    </visual>
    <collision>
      <origin
        xyz="0 0 0"
        rpy="0 0 0" />
      <geometry>
        <mesh
          filename="meshes/link3.STL" />
      </geometry>
    </collision>
  </link>
  <joint
    name="joint3"
    type="revolute">
    <origin
      xyz="0.043182 0.04579 0"
      rpy="0 0 0" />
    <parent
      link="link1" />
    <child
      link="link3" />
    <axis
      xyz="0 0 -1" />
    <limit
      lower="-0.925"
      upper="0"
      effort="100"
      velocity="1" />
    <mimic
      joint="joint1"
      multiplier="-1"
      offset="0" />
  </joint>
  <link
    name="link2">
    <inertial>
      <origin
        xyz="0.010574 -0.012245 -0.011443"
        rpy="0 0 0" />
      <mass
        value="0.031663" />
      <inertia
        ixx="1.0593E-05"
        ixy="6.1069E-06"
        ixz="1.9726E-07"
        iyy="8.1038E-06"
        iyz="-3.1805E-07"
        izz="1.8173E-05" />
    </inertial>
    <visual>
      <origin
        xyz="0 0 0"
        rpy="0 0 0" />
      <geometry>
        <mesh
          filename="meshes/link2.STL" />
      </geometry>
      <material
        name="">
        <color
          rgba="1 1 0.8 1" />
      </material>
    </visual>
    <collision>
      <origin
        xyz="0 0 0"
        rpy="0 0 0" />
      <geometry>
        <mesh
          filename="meshes/link2.STL" />
      </geometry>
    </collision>
  </link>
  <joint
    name="joint2"
    type="revolute">
    <origin
      xyz="0.022278 -0.042628 -0.059518"
      rpy="0 -0.2618 0" />
    <parent
      link="base_link" />
    <child
      link="link2" />
    <axis
      xyz="0 0 -1" />
    <limit
      lower="-0.925"
      upper="0"
      effort="100"
      velocity="1" />
    <mimic
      joint="joint1"
      multiplier="-1"
      offset="0" />
  </joint>
  <link
    name="link4">
    <inertial>
      <origin
        xyz="0.0281972854196394 0.0278445505366352 -0.00938623119932044"
        rpy="0 0 0" />
      <mass
        value="0.0203237501202117" />
      <inertia
        ixx="8.44286661950155E-07"
        ixy="-4.18698059123249E-07"
        ixz="-2.15036110100277E-12"
        iyy="4.90959334176622E-06"
        iyz="2.50859839909565E-14"
        izz="4.888907129178E-06" />
    </inertial>
    <visual>
      <origin
        xyz="0 0 0"
        rpy="0 0 0" />
      <geometry>
        <mesh
          filename="meshes/link4.STL" />
      </geometry>
      <material
        name="">
        <color
          rgba="0.498039215686275 0.498039215686275 0.498039215686275 1" />
      </material>
    </visual>
    <collision>
      <origin
        xyz="0 0 0"
        rpy="0 0 0" />
      <geometry>
        <mesh
          filename="meshes/link4.STL" />
      </geometry>
    </collision>
  </link>
  <joint
    name="joint4"
    type="revolute">
    <origin
      xyz="0.043182 -0.04579 0"
      rpy="0 0 0" />
    <parent
      link="link2" />
    <child
      link="link4" />
    <axis
      xyz="0 0 -1" />
    <limit
      lower="0"
      upper="0.925"
      effort="100"
      velocity="1" />
    <mimic
      joint="joint2"
      multiplier="-1"
      offset="0" />
  </joint>
  <link
    name="link5">
    <inertial>
      <origin
        xyz="0.017198 0.022014 -0.0093515"
        rpy="0 0 0" />
      <mass
        value="0.0090548" />
      <inertia
        ixx="1.7648E-06"
        ixy="-1.0991E-06"
        ixz="-5.2569E-15"
        iyy="1.3379E-06"
        iyz="-2.5144E-17"
        izz="2.3817E-06" />
    </inertial>
    <visual>
      <origin
        xyz="0 0 0"
        rpy="0 0 0" />
      <geometry>
        <mesh
          filename="meshes/link5.STL" />
      </geometry>
      <material
        name="">
        <color
          rgba="0.6 0.6 1 1" />
      </material>
    </visual>
    <collision>
      <origin
        xyz="0 0 0"
        rpy="0 0 0" />
      <geometry>
        <mesh
          filename="meshes/link5.STL" />
      </geometry>
    </collision>
  </link>
  <joint
    name="joint5"
    type="revolute">
    <origin
      xyz="0.037008 0.01989 -0.055571"
      rpy="0 -0.2618 0" />
    <parent
      link="base_link" />
    <child
      link="link5" />
    <axis
      xyz="0 0 -1" />
    <limit
      lower="0"
      upper="0.925"
      effort="100"
      velocity="0" />
    <mimic
      joint="joint1"
      multiplier="1"
      offset="0" />
  </joint>
  <link
    name="link6">
    <inertial>
      <origin
        xyz="0 0 0"
        rpy="0 0 0" />
      <mass
        value="0" />
      <inertia
        ixx="0"
        ixy="0"
        ixz="0"
        iyy="0"
        iyz="0"
        izz="0" />
    </inertial>
    <visual>
      <origin
        xyz="0 0 0"
        rpy="0 0 0" />
      <geometry>
        <mesh
          filename="meshes/link6.STL" />
      </geometry>
      <material
        name="">
        <color
          rgba="0.6 0.6 1 1" />
      </material>
    </visual>
    <collision>
      <origin
        xyz="0 0 0"
        rpy="0 0 0" />
      <geometry>
        <mesh
          filename="meshes/link6.STL" />
      </geometry>
    </collision>
  </link>
  <joint
    name="joint6"
    type="revolute">
    <origin
      xyz="0.037008 -0.019145 -0.055571"
      rpy="0 -0.2618 0" />
    <parent
      link="base_link" />
    <child
      link="link6" />
    <axis
      xyz="0 0 -1" />
    <limit
      lower="-0.925"
      upper="0"
      effort="100"
      velocity="1" />
    <mimic
      joint="joint2"
      multiplier="1"
      offset="0" />
  </joint>
</robot>