<?xml version="1.0" ?>
<mujoco model="generated_scene">
  <compiler angle="radian" meshdir="/home/yuxuan/Code/hirol/HIROLRobotPlatform/assets" texturedir="/home/yuxuan/Code/hirol/HIROLRobotPlatform/assets"/>
  <statistic center="0 0 0.5" extent="2.0"/>
  <visual>
    <headlight diffuse="0.6 0.6 0.6" ambient="0.3 0.3 0.3" specular="0 0 0"/>
    <rgba haze="0.15 0.25 0.35 1"/>
    <global azimuth="-130" elevation="-20"/>
  </visual>
  <default>
    <geom friction="0.7 0.005 0.0001" condim="3" conaffinity="1" contype="1" solref="0.005 1" solimp="0.95 0.99 0.001"/>
    <joint damping="0.01" frictionloss="0.01"/>
    <motor ctrllimited="true" ctrlrange="-1000 1000"/>
    <default class="stable_joint">
      <joint damping="15" frictionloss="5" armature="0.2"/>
    </default>
    <default class="head_joint">
      <joint damping="15" frictionloss="2" armature="0.1"/>
    </default>
    <default class="arm_joint_heavy">
      <joint damping="10" frictionloss="1"/>
    </default>
    <default class="arm_joint_medium">
      <joint damping="5" frictionloss="1"/>
    </default>
    <default class="arm_joint_light">
      <joint damping="2" frictionloss="1"/>
    </default>
  </default>
  <option timestep="0.001" iterations="50" solver="Newton" tolerance="1e-8" ls_iterations="20" noslip_iterations="0" integrator="Euler" gravity="0.0 0.0 -9.81"/>
  <asset>
    <texture type="skybox" builtin="gradient" rgb1="0.3 0.5 0.7" rgb2="0 0 0" width="512" height="3072"/>
    <texture type="2d" name="groundplane" builtin="checker" mark="edge" rgb1="0.2 0.3 0.4" rgb2="0.1 0.2 0.3" markrgb="0.8 0.8 0.8" width="300" height="300"/>
    <material name="groundplane" texture="groundplane" texuniform="true" texrepeat="5 5" reflectance="0.2"/>
    <material name="white" rgba="1 1 1 1"/>
    <material name="gray" rgba="0.753 0.753 0.753 1"/>
    <material name="black" rgba="0.149 0.149 0.149 1"/>
    <mesh name="base_link" file="monte_01/meshes/base_link.STL"/>
    <mesh name="base_link_gripper" file="monte_01/meshes/base_link_gripper.STL"/>
    <mesh name="left_wheel_link" file="monte_01/meshes/left_wheel_link.STL"/>
    <mesh name="right_wheel_link" file="monte_01/meshes/right_wheel_link.STL"/>
    <mesh name="back_wheel_link" file="monte_01/meshes/back_wheel_link.STL"/>
    <mesh name="leg_link" file="monte_01/meshes/leg_link.STL"/>
    <mesh name="hip_link" file="monte_01/meshes/hip_link.STL"/>
    <mesh name="chest_link" file="monte_01/meshes/chest_link.STL"/>
    <mesh name="head_pitch_link" file="monte_01/meshes/head_pitch_link.STL"/>
    <mesh name="left_arm_link_base" file="monte_01/meshes/left_arm_link_base.STL"/>
    <mesh name="arm_link1" file="monte_01/meshes/arm_link1.STL"/>
    <mesh name="arm_link2" file="monte_01/meshes/arm_link2.STL"/>
    <mesh name="arm_link3" file="monte_01/meshes/arm_link3.STL"/>
    <mesh name="arm_link4" file="monte_01/meshes/arm_link4.STL"/>
    <mesh name="arm_link5" file="monte_01/meshes/arm_link5.STL"/>
    <mesh name="arm_link6" file="monte_01/meshes/arm_link6.STL"/>
    <mesh name="left_arm_link_7" file="monte_01/meshes/left_arm_link_7.STL"/>
    <mesh name="right_arm_link_base" file="monte_01/meshes/right_arm_link_base.STL"/>
    <mesh name="right_arm_link_7" file="monte_01/meshes/right_arm_link_7.STL"/>
    <mesh name="hand_link" file="monte_01/meshes/hand_link.STL"/>
    <model name="left_gripper" file="assets/monte_01/urdf/gripper_modular.xml"/>
    <model name="right_gripper" file="assets/monte_01/urdf/gripper_xarm7.xml"/>
  </asset>
  <worldbody>
    <light pos="0 0 1.5" dir="0 0 -1" directional="true"/>
    <geom name="floor" size="0 0 0.05" type="plane" material="groundplane"/>
    <body name="monte_01_base" pos="-0.1 0.0 0.1" quat="1.0 0.0 0.0 0.0">
      <body name="base_platform" pos="0 0 0">
        <inertial pos="0 0 0" mass="50" diaginertia="5 5 5"/>
        <geom type="mesh" contype="0" conaffinity="0" group="1" rgba="0.902 0.902 0.902 1" mesh="base_link"/>
        <geom type="capsule" size="0.0800 0.0481" pos="-0.1774 0.0000 0.2001" quat="0.707 0 0.707 0" rgba="0.5 0.5 0.5 0.3"/>
        <geom pos="0 0.26435 0" quat="0.707105 0.707108 0 0" type="mesh" contype="0" conaffinity="0" group="1" rgba="0.902 0.902 0.902 1" mesh="left_wheel_link"/>
        <geom pos="0 -0.26435 0" quat="0.707105 -0.707108 0 0" type="mesh" contype="0" conaffinity="0" group="1" rgba="0.902 0.902 0.902 1" mesh="right_wheel_link"/>
        <geom pos="-0.355 0.00025 0.0148" type="mesh" contype="0" conaffinity="0" group="1" rgba="0.902 0.902 0.902 1" mesh="back_wheel_link"/>
      </body>
      <body name="leg_link" pos="-0.15685 0 0.38203">
        <inertial pos="0.0245059 -0.00799219 0.174693" quat="0.705443 -0.049007 -0.0490354 0.705368" mass="3.28399" diaginertia="0.0350376 0.0341184 0.00475773"/>
        <joint name="body_joint_1" pos="0 0 0" axis="0 1 0" range="-1.3788 0.50615" class="stable_joint"/>
        <geom type="mesh" contype="0" conaffinity="0" group="1" rgba="0.902 0.902 0.902 1" mesh="leg_link"/>
        <geom type="capsule" size="0.0992 0.1483" pos="0.0190 0.0000 0.1806" rgba="0.5 0.5 0.5 0.3"/>
        <body name="hip_link" pos="0.05 0 0.35348">
          <inertial pos="-0.0241312 0.00886613 0.0419535" quat="0.572988 0.383287 0.359085 0.629154" mass="9.0897" diaginertia="0.0238406 0.01939 0.0157637"/>
          <joint name="body_joint_2" pos="0 0 0" axis="0 1 0" range="-0.50615 2.6005" class="stable_joint"/>
          <geom type="mesh" contype="0" conaffinity="0" group="1" rgba="0.902 0.902 0.902 1" mesh="hip_link"/>
          <geom type="capsule" size="0.0812 0.0215" pos="-0.0214 0.0000 0.0368" rgba="0.5 0.5 0.5 0.3"/>
          <body name="chest_link" pos="-0.05 0 0.49">
            <inertial pos="-0.0038589 0.000831105 -0.159919" quat="0.998725 0.00418036 0.0133576 0.0484987" mass="10.6506" diaginertia="0.0851562 0.0772272 0.0430473"/>
            <joint name="body_joint_3" pos="0 0 0" axis="0 0 -1" range="-1.2915 1.2915" class="stable_joint"/>
            <geom type="mesh" contype="0" conaffinity="0" group="1" rgba="0.902 0.902 0.902 1" mesh="chest_link"/>
            <geom type="capsule" size="0.0949 0.0905" pos="-0.0066 0.0000 -0.1096" rgba="0.5 0.5 0.5 0.3"/>
            <geom pos="0 0.025 0" quat="1 0 0 0" type="mesh" contype="0" conaffinity="0" group="1" rgba="0.3922 0.3529 1 1" mesh="left_arm_link_base"/>
            <geom pos="0 -0.025 0" quat="1 0 0 0" type="mesh" contype="0" conaffinity="0" group="1" rgba="0.3922 0.3529 1 1" mesh="right_arm_link_base"/>
            <body name="head_yaw_link" pos="-0.0065303 0 0.15766">
              <inertial pos="-5.78417e-05 -0.00454218 -0.0338959" quat="0.487598 0.87279 -0.0172294 -0.0137859" mass="0.442755" diaginertia="0.000126387 0.000116255 0.000114828"/>
              <joint name="head_joint_1" pos="0 0 0" axis="0 0 1" range="-1.55334 1.55334" class="head_joint"/>
              <body name="head_pitch_link">
                <inertial pos="0.0619108 -0.0007342 0.0254911" quat="0.620889 0.610002 -0.34213 0.336218" mass="0.315564" diaginertia="0.000299509 0.000271913 9.92176e-05"/>
                <joint name="head_joint_2" pos="0 0 0" axis="0 1 0" range="-0.418879 0.418879" class="head_joint"/>
                <geom type="mesh" contype="0" conaffinity="0" group="1" rgba="0.902 0.902 0.902 1" mesh="head_pitch_link"/>
                <geom type="capsule" size="0.0916 0.0065" pos="0.0232 0.0000 0.0329" quat="0.707 0.707 0 0" rgba="0.5 0.5 0.5 0.3"/>
              </body>
            </body>
            <body name="left_arm_link_1" pos="0.000127977 0.29087 -0.00113089" quat="-0.499265 0.500734 0.500175 0.499824">
              <inertial pos="-0.0042142 0.02821 -0.0087788" quat="0.917781 -0.277115 0.0606681 0.277858" mass="0.42603" diaginertia="0.00144551 0.00137757 0.000823511"/>
              <joint name="left_arm_joint_1" range="-6.28144 6.28144" class="arm_joint_heavy"/>
              <geom type="mesh" contype="0" conaffinity="0" group="1" rgba="0.902 0.902 0.902 1" mesh="arm_link1"/>
              <geom type="capsule" size="0.0533 0.0290" pos="-0.0000 0.0009 -0.0337" rgba="0.5 0.5 0.5 0.3"/>
              <body name="left_arm_link_2" pos="-0.00040317 4.81717e-06 -1.1089e-08" quat="0.49998 -0.500928 -0.500189 -0.4989">
                <inertial pos="-3.3178e-05 -0.12849 0.026337" quat="0.447793 0.894132 -0.00224061 0.00218314" mass="0.56095" diaginertia="0.00319151 0.00311598 0.000980804"/>
                <joint name="left_arm_joint_2" range="-0.471687 3.59545" class="arm_joint_heavy"/>
                <geom type="mesh" contype="0" conaffinity="0" group="1" rgba="0.902 0.902 0.902 1" mesh="arm_link2"/>
                <geom type="capsule" size="0.0650 0.0507" pos="-0.0000 -0.0671 0.0370" quat="0.707 0.707 0 0" rgba="0.5 0.5 0.5 0.3"/>
                <body name="left_arm_link_3" pos="0.00061189 -0.292495 -0.000980908" quat="0.499245 0.500922 -0.500753 0.499077">
                  <inertial pos="0.04223 -0.023258 -0.0096674" quat="0.883205 0.339803 0.323238 0.000542237" mass="0.44463" diaginertia="0.00133227 0.00119126 0.000780475"/>
                  <joint name="left_arm_joint_3" range="-7.81898 4.67748" class="arm_joint_medium"/>
                  <geom type="mesh" contype="0" conaffinity="0" group="1" rgba="0.902 0.902 0.902 1" mesh="arm_link3"/>
                  <geom type="capsule" size="0.0640 0.0132" pos="0.0262 0.0113 -0.0327" rgba="0.5 0.5 0.5 0.3"/>
                  <body name="left_arm_link_4" pos="0.0520853 0.00107756 3.37622e-06" quat="0.00110785 -0.00110785 -0.708067 0.706143">
                    <inertial pos="0.067148 -0.10732 0.024479" quat="0.0654142 0.483317 -0.738663 0.465298" mass="0.52387" diaginertia="0.00288984 0.00282705 0.000894409"/>
                    <joint name="left_arm_joint_4" range="-3.10643 0.750365" class="arm_joint_medium"/>
                    <geom type="mesh" contype="0" conaffinity="0" group="1" rgba="0.902 0.902 0.902 1" mesh="arm_link4"/>
                    <geom type="capsule" size="0.0803 0.0232" pos="0.0391 -0.0589 0.0320" quat="0.707 0.707 0 0" rgba="0.5 0.5 0.5 0.3"/>
                    <body name="left_arm_link_5" pos="0.0756306 -0.342383 0.00185931" quat="0.501854 0.499709 -0.497571 0.500856">
                      <inertial pos="-0.00023397 0.036705 -0.080064" quat="0.981064 -0.19003 0.00637998 0.0369004" mass="0.18554" diaginertia="0.00099553 0.000988613 0.000247126"/>
                      <joint name="left_arm_joint_5" range="-7.82063 4.67745" class="arm_joint_medium"/>
                      <geom type="mesh" contype="0" conaffinity="0" group="1" rgba="0.902 0.902 0.902 1" mesh="arm_link5"/>
                      <geom type="capsule" size="0.0553 0.0548" pos="0.0000 0.0206 -0.0716" rgba="0.5 0.5 0.5 0.3"/>
                      <body name="left_arm_link_6" pos="0.000937545 -0.0036436 -6.98052e-05" quat="0.700299 0.713849 -0.00105634 -0.000255129">
                        <inertial pos="0.058911 0.028469 0.0068428" quat="-0.188705 0.793535 0.166088 0.554173" mass="0.31344" diaginertia="0.000827892 0.000768871 0.000386708"/>
                        <joint name="left_arm_joint_6" range="-1.69122 2.87297" class="arm_joint_light"/>
                        <geom type="mesh" contype="0" conaffinity="0" group="1" rgba="0.902 0.902 0.902 1" mesh="arm_link6"/>
                        <geom type="capsule" size="0.0514 0.0254" pos="0.0381 0.0144 0.0109" quat="0.707 0 0.707 0" rgba="0.5 0.5 0.5 0.3"/>
                        <body name="left_arm_link_7" pos="0.0761231 0.0966977 -0.00156838" quat="0.503784 0.495446 0.496095 -0.504604">
                          <inertial pos="-0.000560743 -0.000236717 -0.0436157" quat="0.707378 -0.0122802 -0.0127115 0.706615" mass="1.73521" diaginertia="0.0041315 0.00350447 0.00130611"/>
                          <joint name="left_arm_joint_7" range="-6.28144 6.28144" class="arm_joint_light"/>
                          <geom type="mesh" contype="0" conaffinity="0" group="1" rgba="0.3922 0.3529 1 1" mesh="left_arm_link_7"/>
                          <geom type="capsule" size="0.0277 0.0188" pos="-0.0075 0.0000 0.0165" quat="0.707 0 0.707 0" rgba="0.5 0.5 0.5 0.3"/>
                          <site name="left_gripper_attachment" pos="0 0 0" quat="0 1 0 0"/>
                          <attach model="left_gripper" prefix="left_corenetic_" body="gripper_base"/>
                        </body>
                      </body>
                    </body>
                  </body>
                </body>
              </body>
            </body>
            <body name="right_arm_link_1" pos="-0.000119545 -0.290503 -0.00140256" quat="0.499931 0.500068 -0.500981 0.499018">
              <inertial pos="-0.0042142 0.02821 -0.0087788" quat="0.917781 -0.277115 0.0606681 0.277858" mass="0.42603" diaginertia="0.00144551 0.00137757 0.000823511"/>
              <joint name="right_arm_joint_1" range="-6.28144 6.28144" class="arm_joint_heavy"/>
              <geom type="mesh" contype="0" conaffinity="0" group="1" rgba="0.902 0.902 0.902 1" mesh="arm_link1"/>
              <geom type="capsule" size="0.0533 0.0290" pos="-0.0000 0.0009 -0.0337" rgba="0.5 0.5 0.5 0.3"/>
              <body name="right_arm_link_2" pos="0.00018849 4.00533e-05 -2.299e-07" quat="0.499144 -0.501901 -0.500968 -0.497978">
                <inertial pos="-3.3178e-05 -0.12849 0.026337" quat="0.447793 0.894132 -0.00224061 0.00218314" mass="0.56095" diaginertia="0.00319151 0.00311598 0.000980804"/>
                <joint name="right_arm_joint_2" range="-0.471687 3.59545" class="arm_joint_heavy"/>
                <geom type="mesh" contype="0" conaffinity="0" group="1" rgba="0.902 0.902 0.902 1" mesh="arm_link2"/>
                <geom type="capsule" size="0.0650 0.0507" pos="-0.0000 -0.0671 0.0370" quat="0.707 0.707 0 0" rgba="0.5 0.5 0.5 0.3"/>
                <body name="right_arm_link_3" pos="0.000110741 -0.292526 -0.00168114" quat="0.498311 0.501795 -0.501074 0.498811">
                  <inertial pos="0.04223 -0.023258 -0.0096674" quat="0.883205 0.339803 0.323238 0.000542237" mass="0.44463" diaginertia="0.00133227 0.00119126 0.000780475"/>
                  <joint name="right_arm_joint_3" range="-7.81908 4.67748" class="arm_joint_medium"/>
                  <geom type="mesh" contype="0" conaffinity="0" group="1" rgba="0.902 0.902 0.902 1" mesh="arm_link3"/>
                  <geom type="capsule" size="0.0640 0.0132" pos="0.0262 0.0113 -0.0327" rgba="0.5 0.5 0.5 0.3"/>
                  <body name="right_arm_link_4" pos="0.052001 0.00080659 4.08215e-06" quat="0.00184333 -0.00270193 -0.708364 0.70584">
                    <inertial pos="0.067148 -0.10732 0.024479" quat="0.0654142 0.483317 -0.738663 0.465298" mass="0.52387" diaginertia="0.00288984 0.00282705 0.000894409"/>
                    <joint name="right_arm_joint_4" range="-3.2114 0.750476" class="arm_joint_medium"/>
                    <geom type="mesh" contype="0" conaffinity="0" group="1" rgba="0.902 0.902 0.902 1" mesh="arm_link4"/>
                    <geom type="capsule" size="0.0803 0.0232" pos="0.0391 -0.0589 0.0320" quat="0.707 0.707 0 0" rgba="0.5 0.5 0.5 0.3"/>
                    <body name="right_arm_link_5" pos="0.0770178 -0.341838 -0.000191496" quat="0.500546 0.502664 -0.497603 0.499174">
                      <inertial pos="-0.00023397 0.036705 -0.080064" quat="0.981064 -0.19003 0.00637998 0.0369004" mass="0.18554" diaginertia="0.00099553 0.000988613 0.000247126"/>
                      <joint name="right_arm_joint_5" range="-7.8191 4.67748" class="arm_joint_medium"/>
                      <geom type="mesh" contype="0" conaffinity="0" group="1" rgba="0.902 0.902 0.902 1" mesh="arm_link5"/>
                      <geom type="capsule" size="0.0553 0.0548" pos="0.0000 0.0206 -0.0716" rgba="0.5 0.5 0.5 0.3"/>
                      <body name="right_arm_link_6" pos="0.000155265 -0.00361337 -6.4194e-05" quat="0.700798 0.713358 -0.0016632 0.000951125">
                        <inertial pos="0.058911 0.028469 0.0068428" quat="-0.188705 0.793535 0.166088 0.554173" mass="0.31344" diaginertia="0.000827892 0.000768871 0.000386708"/>
                        <joint name="right_arm_joint_6" range="-1.69122 2.81173" class="arm_joint_light"/>
                        <geom type="mesh" contype="0" conaffinity="0" group="1" rgba="0.902 0.902 0.902 1" mesh="arm_link6"/>
                        <geom type="capsule" size="0.0514 0.0254" pos="0.0381 0.0144 0.0109" quat="0.707 0 0.707 0" rgba="0.5 0.5 0.5 0.3"/>
                        <body name="right_arm_link_7" pos="0.0770371 0.0959785 -0.00181105" quat="0.505361 0.494828 -0.494756 0.504947">
                          <inertial pos="0.00112135 -0.000230969 -0.0436157" quat="0.706898 0.0147814 0.0144714 0.707013" mass="1.73521" diaginertia="0.00412987 0.00350549 0.00130346"/>
                          <joint name="right_arm_joint_7" range="-6.24825 6.24825" class="arm_joint_light"/>
                          <geom type="mesh" contype="0" conaffinity="0" group="1" rgba="0.3922 0.3529 1 1" mesh="right_arm_link_7"/>
                          <geom type="capsule" size="0.0277 0.0188" pos="0.0075 0.0000 0.0165" quat="0.707 0 0.707 0" rgba="0.5 0.5 0.5 0.3"/>
                          <site name="right_gripper_attachment" pos="0 0 0" quat="0 1 0 0"/>
                          <attach model="right_gripper" prefix="right_xarm7_" body="xarm_gripper_base"/>
                        </body>
                      </body>
                    </body>
                  </body>
                </body>
              </body>
            </body>
          </body>
        </body>
      </body>
    </body>
    <body name="table" pos="0.5 0.0 0.6" quat="0.0 0.0 0.0 1.0">
      <inertial pos="0 0 0.025" mass="10" diaginertia="0.6 0.5 0.1"/>
      <geom type="box" size="0.425 0.375 0.05" rgba="0.8 0.6 0.4 1"/>
    </body>
    <body name="box_1" pos="0.3 0.2 0.8" quat="0.0 0.0 0.0 1.0">
      <joint name="box_1_joint" type="free" damping="0.001"/>
      <inertial pos="0 0 0.05" mass="0.5" diaginertia="0.005 0.005 0.005"/>
      <geom name="box_1_box_main" size="0.05 0.05 0.05" pos="0 0 0.05" type="box" rgba="1 0 0 1" friction="0.7 0.005 0.0001" solref="0.002 1" solimp="0.99 0.999 0.0001"/>
      <geom name="box_1_box_collision" size="0.05 0.05 0.05" pos="0 0 0.05" type="box" contype="1" conaffinity="1" group="0" friction="0.7 0.005 0.0001" solref="0.002 1" solimp="0.99 0.999 0.0001"/>
    </body>
    <body name="box_2" pos="0.3 -0.2 0.8" quat="0.0 0.0 0.0 1.0">
      <joint name="box_2_joint" type="free" damping="0.001"/>
      <inertial pos="0 0 0.05" mass="0.5" diaginertia="0.005 0.005 0.005"/>
      <geom name="box_2_box_main" size="0.05 0.05 0.05" pos="0 0 0.05" type="box" rgba="1 0 0 1" friction="0.7 0.005 0.0001" solref="0.002 1" solimp="0.99 0.999 0.0001"/>
      <geom name="box_2_box_collision" size="0.05 0.05 0.05" pos="0 0 0.05" type="box" contype="1" conaffinity="1" group="0" friction="0.7 0.005 0.0001" solref="0.002 1" solimp="0.99 0.999 0.0001"/>
    </body>
  </worldbody>
  <actuator>
    <position name="body_joint_1_ctrl" joint="body_joint_1" ctrlrange="-1.3788 0.50615" kp="8000" dampratio="1.0"/>
    <position name="body_joint_2_ctrl" joint="body_joint_2" ctrlrange="-0.50615 2.6005" kp="6000" dampratio="1.0"/>
    <position name="body_joint_3_ctrl" joint="body_joint_3" ctrlrange="-1.2915 1.2915" kp="4000" dampratio="1.0"/>
    <position name="head_joint_1_ctrl" joint="head_joint_1" ctrlrange="-1.553343034 1.553343034" kp="500"/>
    <position name="head_joint_2_ctrl" joint="head_joint_2" ctrlrange="-0.41887902 0.41887902" kp="500"/>
    <position name="left_arm_joint_1_ctrl" joint="left_arm_joint_1" ctrlrange="-6.281439781188965 6.281439781188965" kp="1500"/>
    <position name="left_arm_joint_2_ctrl" joint="left_arm_joint_2" ctrlrange="-0.47168713768005377 3.595448434753418" kp="1500"/>
    <position name="left_arm_joint_3_ctrl" joint="left_arm_joint_3" ctrlrange="-7.818976819915772 4.67748266418457" kp="1200"/>
    <position name="left_arm_joint_4_ctrl" joint="left_arm_joint_4" ctrlrange="-3.1064263031446933 0.7503646604156495" kp="1200"/>
    <position name="left_arm_joint_5_ctrl" joint="left_arm_joint_5" ctrlrange="-7.820627630157471 4.677452146606445" kp="1000"/>
    <position name="left_arm_joint_6_ctrl" joint="left_arm_joint_6" ctrlrange="-1.6912236213684082 2.872974157333374" kp="1000"/>
    <position name="left_arm_joint_7_ctrl" joint="left_arm_joint_7" ctrlrange="-6.281439781188965 6.281439781188965" kp="1000"/>
    <position name="right_arm_joint_1_ctrl" joint="right_arm_joint_1" ctrlrange="-6.281439781188965 6.281439781188965" kp="1500"/>
    <position name="right_arm_joint_2_ctrl" joint="right_arm_joint_2" ctrlrange="-0.47168713768005377 3.595448434753418" kp="1500"/>
    <position name="right_arm_joint_3_ctrl" joint="right_arm_joint_3" ctrlrange="-7.819076478881836 4.67748266418457" kp="1200"/>
    <position name="right_arm_joint_4_ctrl" joint="right_arm_joint_4" ctrlrange="-3.211403385605812 0.75047600189209" kp="1200"/>
    <position name="right_arm_joint_5_ctrl" joint="right_arm_joint_5" ctrlrange="-7.81909936706543 4.6774769421386715" kp="1000"/>
    <position name="right_arm_joint_6_ctrl" joint="right_arm_joint_6" ctrlrange="-1.6912236213684082 2.811725378036499" kp="1000"/>
    <position name="right_arm_joint_7_ctrl" joint="right_arm_joint_7" ctrlrange="-6.248254776000977 6.248254776000977" kp="1000"/>
    <motor name="body_joint_1_gravity_comp" joint="body_joint_1" gear="150"/>
    <motor name="body_joint_2_gravity_comp" joint="body_joint_2" gear="80"/>
  </actuator>
</mujoco>