<mujoco model="robot_description">
  <compiler angle="radian" meshdir="../meshes/"/>

  <asset>
    <mesh name="base_link" content_type="model/stl" file="base_link.STL"/>
    <mesh name="left_wheel_link" content_type="model/stl" file="left_wheel_link.STL"/>
    <mesh name="right_wheel_link" content_type="model/stl" file="right_wheel_link.STL"/>
    <mesh name="back_wheel_link" content_type="model/stl" file="back_wheel_link.STL"/>
    <mesh name="leg_link" content_type="model/stl" file="leg_link.STL"/>
    <mesh name="hip_link" content_type="model/stl" file="hip_link.STL"/>
    <mesh name="chest_link" content_type="model/stl" file="chest_link.STL"/>
    <mesh name="head_pitch_link" content_type="model/stl" file="head_pitch_link.STL"/>
    <mesh name="left_arm_link_base" content_type="model/stl" file="left_arm_link_base.STL"/>
    <mesh name="arm_link1" content_type="model/stl" file="arm_link1.STL"/>
    <mesh name="arm_link2" content_type="model/stl" file="arm_link2.STL"/>
    <mesh name="arm_link3" content_type="model/stl" file="arm_link3.STL"/>
    <mesh name="arm_link4" content_type="model/stl" file="arm_link4.STL"/>
    <mesh name="arm_link5" content_type="model/stl" file="arm_link5.STL"/>
    <mesh name="arm_link6" content_type="model/stl" file="arm_link6.STL"/>
    <mesh name="left_arm_link_7" content_type="model/stl" file="left_arm_link_7.STL"/>
    <mesh name="right_arm_link_base" content_type="model/stl" file="right_arm_link_base.STL"/>
    <mesh name="right_arm_link_7" content_type="model/stl" file="right_arm_link_7.STL"/>
    <mesh name="gripper_base_link" content_type="model/stl" file="gripper_base_link.STL"/>
    <mesh name="drive_gear" content_type="model/stl" file="drive_gear.STL"/>
    <mesh name="right_outer_knuckle" content_type="model/stl" file="right_outer_knuckle.STL"/>
    <mesh name="right_finger" content_type="model/stl" file="right_finger.STL"/>
    <mesh name="right_inner_knuckle" content_type="model/stl" file="right_inner_knuckle.STL"/>
    <mesh name="left_outer_knuckle" content_type="model/stl" file="left_outer_knuckle.STL"/>
    <mesh name="left_finger" content_type="model/stl" file="left_finger.STL"/>
    <mesh name="left_inner_knuckle" content_type="model/stl" file="left_inner_knuckle.STL"/>
  </asset>

  <worldbody>
    <body name="base_car">
      <geom type="mesh" contype="0" conaffinity="0" group="1" density="0" rgba="0.902 0.902 0.902 1" mesh="base_link"/>
      <geom type="mesh" rgba="0.902 0.902 0.902 1" mesh="base_link"/>
      <geom pos="0 0.26435 0" quat="0.707105 0.707108 0 0" type="mesh" contype="0" conaffinity="0" group="1" density="0" rgba="0.902 0.902 0.902 1" mesh="left_wheel_link"/>
      <geom pos="0 -0.26435 0" quat="0.707105 -0.707108 0 0" type="mesh" contype="0" conaffinity="0" group="1" density="0" rgba="0.902 0.902 0.902 1" mesh="right_wheel_link"/>
      <geom pos="-0.355 0.00025 0.0148" type="mesh" contype="0" conaffinity="0" group="1" density="0" rgba="0.902 0.902 0.902 1" mesh="back_wheel_link"/>
      <body name="leg_link" pos="-0.15685 0 0.38203">
        <inertial pos="0.0245059 -0.00799219 0.174693" quat="0.705443 -0.049007 -0.0490354 0.705368" mass="3.28399" diaginertia="0.0350376 0.0341184 0.00475773"/>
        <!-- <joint name="body_joint_1" pos="0 0 0" axis="0 1 0" range="-1.3788 0.50615"/> -->
        <geom type="mesh" contype="0" conaffinity="0" group="1" density="0" rgba="0.902 0.902 0.902 1" mesh="leg_link"/>
        <geom type="mesh" rgba="0.902 0.902 0.902 1" mesh="leg_link"/>
        <body name="hip_link" pos="0.05 0 0.35348">
          <inertial pos="-0.0241312 0.00886613 0.0419535" quat="0.572988 0.383287 0.359085 0.629154" mass="9.0897" diaginertia="0.0238406 0.01939 0.0157637"/>
          <!-- <joint name="body_joint_2" pos="0 0 0" axis="0 1 0" range="-0.50615 2.6005"/> -->
          <geom type="mesh" contype="0" conaffinity="0" group="1" density="0" rgba="0.902 0.902 0.902 1" mesh="hip_link"/>
          <geom type="mesh" rgba="0.902 0.902 0.902 1" mesh="hip_link"/>
          <body name="chest_link" pos="-0.05 0 0.49">
            <inertial pos="-0.00382881 -0.000925551 -0.159919" quat="0.985224 0.00907546 0.0116975 0.17063" mass="10.6506" diaginertia="0.0803473 0.0779482 0.0371319"/>
            <!-- <joint name="body_joint_3" pos="0 0 0" axis="0 0 -1" range="-1.2915 1.2915"/> -->
            <geom type="mesh" contype="0" conaffinity="0" group="1" density="0" rgba="0.902 0.902 0.902 1" mesh="chest_link"/>
            <geom type="mesh" rgba="0.902 0.902 0.902 1" mesh="chest_link"/>
            <geom pos="0 0.025 0" quat="1 0 0 0" type="mesh" contype="0" conaffinity="0" group="1" density="0" rgba="0.3922 0.3529 1 1" mesh="left_arm_link_base"/>
            <geom pos="0 0.025 0" quat="1 0 0 0" type="mesh" rgba="0.3922 0.3529 1 1" mesh="left_arm_link_base"/>
            <geom pos="0 -0.025 0" quat="1 0 0 0" type="mesh" contype="0" conaffinity="0" group="1" density="0" rgba="0.3922 0.3529 1 1" mesh="right_arm_link_base"/>
            <geom pos="0 -0.025 0" quat="1 0 0 0" type="mesh" rgba="0.3922 0.3529 1 1" mesh="right_arm_link_base"/>
            <body name="head_yaw_link" pos="-0.0065303 0 0.15766">
              <inertial pos="-5.78417e-05 -0.00454218 -0.0338959" quat="0.487598 0.87279 -0.0172294 -0.0137859" mass="0.442755" diaginertia="0.000126387 0.000116255 0.000114828"/>
              <!-- <joint name="head_joint_1" pos="0 0 0" axis="0 0 1" range="-1.55334 1.55334"/> -->
              <body name="head_pitch_link">
                <inertial pos="0.0619108 -0.0007342 0.0254911" quat="0.620889 0.620002 -0.34213 0.336218" mass="0.315564" diaginertia="0.000299509 0.000271913 9.92176e-05"/>
                <!-- <joint name="head_joint_2" pos="0 0 0" axis="0 1 0" range="-0.418879 0.418879"/> -->
                <geom type="mesh" contype="0" conaffinity="0" group="1" density="0" rgba="0.902 0.902 0.902 1" mesh="head_pitch_link"/>
                <geom type="mesh" rgba="0.902 0.902 0.902 1" mesh="head_pitch_link"/>
              </body>
            </body>
            <body name="left_arm_link_1" pos="0.000127977 0.29087 -0.00113089" quat="-0.499265 0.500734 0.500175 0.499824">
              <inertial pos="-0.0042142 0.02821 -0.0087788" quat="0.917781 -0.277115 0.0606681 0.277858" mass="0.42603" diaginertia="0.00144551 0.00137757 0.000823511"/>
              <joint name="left_arm_joint_1" pos="0 0 0" axis="0 0 1" range="-6.28144 6.28144" actuatorfrcrange="-50 50" damping="10" frictionloss="1"/>
              <geom type="mesh" contype="0" conaffinity="0" group="1" density="0" rgba="0.902 0.902 0.902 1" mesh="arm_link1"/>
              <geom type="mesh" rgba="0.902 0.902 0.902 1" mesh="arm_link1"/>
              <body name="left_arm_link_2" pos="-0.00040317 4.81717e-06 -1.1089e-08" quat="0.49998 -0.500928 -0.500189 -0.4989">
                <inertial pos="-3.3178e-05 -0.12849 0.026337" quat="0.447793 0.894132 -0.00224061 0.00218314" mass="0.56095" diaginertia="0.00319151 0.00311598 0.000980804"/>
                <joint name="left_arm_joint_2" pos="0 0 0" axis="0 0 1" range="-0.471687 3.59545" actuatorfrcrange="-50 50" damping="10" frictionloss="1"/>
                <geom type="mesh" contype="0" conaffinity="0" group="1" density="0" rgba="0.902 0.902 0.902 1" mesh="arm_link2"/>
                <geom type="mesh" rgba="0.902 0.902 0.902 1" mesh="arm_link2"/>
                <body name="left_arm_link_3" pos="0.00061189 -0.292495 -0.000980908" quat="0.499245 0.500922 -0.500753 0.499077">
                  <inertial pos="0.04223 -0.023258 -0.0096674" quat="0.883205 0.339803 0.323238 0.000542237" mass="0.44463" diaginertia="0.00133227 0.00119126 0.000780475"/>
                  <joint name="left_arm_joint_3" pos="0 0 0" axis="0 0 1" range="-7.81898 4.67748" actuatorfrcrange="-30 30" damping="5" frictionloss="1"/>
                  <geom type="mesh" contype="0" conaffinity="0" group="1" density="0" rgba="0.902 0.902 0.902 1" mesh="arm_link3"/>
                  <geom type="mesh" rgba="0.902 0.902 0.902 1" mesh="arm_link3"/>
                  <body name="left_arm_link_4" pos="0.0520853 0.00107756 3.37622e-06" quat="0.00110785 -0.00110785 -0.708067 0.706143">
                    <inertial pos="0.067148 -0.10732 0.024479" quat="0.0654142 0.483317 -0.738663 0.465298" mass="0.52387" diaginertia="0.00288984 0.00282705 0.000894409"/>
                    <joint name="left_arm_joint_4" pos="0 0 0" axis="0 0 1" range="-3.10643 0.750365" actuatorfrcrange="-30 30" damping="5" frictionloss="1"/>
                    <geom type="mesh" contype="0" conaffinity="0" group="1" density="0" rgba="0.902 0.902 0.902 1" mesh="arm_link4"/>
                    <geom type="mesh" rgba="0.902 0.902 0.902 1" mesh="arm_link4"/>
                    <body name="left_arm_link_5" pos="0.0756306 -0.342383 0.00185931" quat="0.501854 0.499709 -0.497571 0.500856">
                      <inertial pos="-0.00023397 0.036705 -0.080064" quat="0.981064 -0.19003 0.00637998 0.0369004" mass="0.18554" diaginertia="0.00099553 0.000988613 0.000247126"/>
                      <joint name="left_arm_joint_5" pos="0 0 0" axis="0 0 1" range="-7.82063 4.67745" actuatorfrcrange="-30 30" damping="5" frictionloss="1"/>
                      <geom type="mesh" contype="0" conaffinity="0" group="1" density="0" rgba="0.902 0.902 0.902 1" mesh="arm_link5"/>
                      <geom type="mesh" rgba="0.902 0.902 0.902 1" mesh="arm_link5"/>
                      <body name="left_arm_link_6" pos="0.000937545 -0.0036436 -6.98052e-05" quat="0.700299 0.713849 -0.00105634 -0.000255129">
                        <inertial pos="0.058911 0.028469 0.0068428" quat="-0.188705 0.793535 0.166088 0.554173" mass="0.31344" diaginertia="0.000827892 0.000768871 0.000386708"/>
                        <joint name="left_arm_joint_6" pos="0 0 0" axis="0 0 1" range="-1.69122 2.87297" actuatorfrcrange="-20 20" damping="2" frictionloss="1"/>
                        <geom type="mesh" contype="0" conaffinity="0" group="1" density="0" rgba="0.902 0.902 0.902 1" mesh="arm_link6"/>
                        <geom type="mesh" rgba="0.902 0.902 0.902 1" mesh="arm_link6"/>
                        <body name="left_arm_link_7" pos="0.0761231 0.0966977 -0.00156838" quat="0.503784 0.495446 0.496095 -0.504604">
                          <inertial pos="-0.00360108 -0.000549587 0.0171849" quat="0.0330765 0.69212 0.0210084 0.720718" mass="0.395374" diaginertia="0.000306377 0.000266605 0.000194434"/>
                          <joint name="left_arm_joint_7" pos="0 0 0" axis="0 0 -1" range="-6.28144 6.28144" actuatorfrcrange="-20 20" damping="2" frictionloss="1"/>
                          <geom type="mesh" contype="0" conaffinity="0" group="1" density="0" rgba="0.3922 0.3529 1 1" mesh="left_arm_link_7"/>
                          <geom type="mesh" rgba="0.3922 0.3529 1 1" mesh="left_arm_link_7"/>
                          <geom quat="0.000796327 1 0 0" type="mesh" contype="0" conaffinity="0" group="1" density="0" rgba="0.89804 0.91765 0.92941 1" mesh="gripper_base_link"/>
                          <geom quat="0.000796327 1 0 0" type="mesh" rgba="0.89804 0.91765 0.92941 1" mesh="gripper_base_link"/>
                          <body name="left_drive_gear" pos="0.0011556 -0.0121573 -0.0359807" quat="0 0 0.3826834 0.9238795">
                            <inertial pos="-3.30863e-05 0 1.19034e-05" quat="0.406662 0.578469 0.578469 0.406662" mass="0.000219454" diaginertia="2.46049e-09 1.69299e-09 1.68169e-09"/>
                            <!-- <joint name="left_drive_gear_joint" pos="0 0 0" axis="0 1 0" range="0 5.8469" actuatorfrcrange="-50 50"/> -->
                            <geom type="mesh" contype="0" conaffinity="0" group="1" density="0" rgba="1 1 1 1" mesh="drive_gear"/>
                            <geom type="mesh" rgba="1 1 1 1" mesh="drive_gear"/>
                          </body>
                          <body name="left_right_outer_knuckle" pos="0.03375 -0.0121884 -0.0555157" quat="0.000796327 1 0 0">
                            <inertial pos="0.0101367 -0.0106013 0.026909" quat="0.744778 0.0907976 0.0929397 0.654541" mass="0.0201205" diaginertia="1.64045e-05 1.61602e-05 2.01288e-06"/>
                            <!-- <joint name="left_right_outer_knuckle_joint" pos="0 0 0" axis="0 1 0" range="0 0.75" actuatorfrcrange="-50 50"/> -->
                            <geom type="mesh" contype="0" conaffinity="0" group="1" density="0" rgba="1 1 1 1" mesh="right_outer_knuckle"/>
                            <geom type="mesh" rgba="1 1 1 1" mesh="right_outer_knuckle"/>
                            <body name="left_right_finger" pos="0.0185706 -0.0121 0.0778147">
                              <inertial pos="-0.0327727 -0.000698948 0.0346732" quat="0.981928 0.0388869 -0.181266 0.0380528" mass="0.036312" diaginertia="6.10124e-06 4.94402e-06 2.82504e-06"/>
                              <!-- <joint name="left_right_finger_joint" pos="0 0 0" axis="0 -1 0" range="0 0.75" actuatorfrcrange="-50 50"/> -->
                              <geom type="mesh" contype="0" conaffinity="0" group="1" density="0" rgba="0.898039 0.917647 0.929412 1" mesh="right_finger"/>
                              <geom type="mesh" rgba="0.898039 0.917647 0.929412 1" mesh="right_finger"/>
                            </body>
                          </body>
                          <body name="left_right_inner_knuckle" pos="0.007 0.000262066 -0.0866065" quat="0.000796327 1 0 0">
                            <inertial pos="0.0165754 1.41152e-08 0.030873" quat="0.70183 0.0862093 0.086209 0.701833" mass="0.0178591" diaginertia="1.36612e-05 1.32419e-05 1.68573e-06"/>
                            <!-- <joint name="left_right_inner_knuckle_joint" pos="0 0 0" axis="0 1 0" range="0 0.75" actuatorfrcrange="-50 50"/> -->
                            <geom type="mesh" contype="0" conaffinity="0" group="1" density="0" rgba="0.898039 0.917647 0.929412 1" mesh="right_inner_knuckle"/>
                            <geom type="mesh" rgba="0.898039 0.917647 0.929412 1" mesh="right_inner_knuckle"/>
                          </body>
                          <body name="left_left_outer_knuckle" pos="-0.03375 -0.0146884 -0.0555117" quat="0.000796327 1 0 0">
                            <inertial pos="-0.0187019 -0.0139951 0.0249289" quat="0.667096 -0.223958 -0.234709 0.670624" mass="0.0386243" diaginertia="3.29051e-05 2.86663e-05 7.92113e-06"/>
                            <!-- <joint name="left_left_outer_knuckle_joint" pos="0 0 0" axis="0 -1 0" range="0 0.75" actuatorfrcrange="-50 50"/> -->
                            <geom type="mesh" contype="0" conaffinity="0" group="1" density="0" rgba="1 1 1 1" mesh="left_outer_knuckle"/>
                            <geom type="mesh" rgba="1 1 1 1" mesh="left_outer_knuckle"/>
                            <body name="left_left_finger" pos="-0.0185764 -0.006 0.0778133">
                              <inertial pos="0.0368553 -0.00948093 0.0371392" quat="0.988534 0.0600377 0.131147 -0.044681" mass="0.0455798" diaginertia="7.86432e-06 6.42439e-06 3.39572e-06"/>
                              <!-- <joint name="left_left_finger_joint" pos="0 0 0" axis="0 1 0" range="0 0.75" actuatorfrcrange="-50 50"/> -->
                              <geom type="mesh" contype="0" conaffinity="0" group="1" density="0" rgba="0.898039 0.917647 0.929412 1" mesh="left_finger"/>
                              <geom type="mesh" rgba="0.898039 0.917647 0.929412 1" mesh="left_finger"/>
                            </body>
                          </body>
                          <body name="left_left_inner_knuckle" pos="-0.007 -0.0190379 -0.0865758" quat="0.000796327 1 0 0">
                            <inertial pos="-0.0251383 -0.0193 0.020239" quat="0.305321 0.637793 0.637793 0.305321" mass="0.0371734" diaginertia="2.84355e-05 1.87893e-05 1.22822e-05"/>
                            <!-- <joint name="left_left_inner_knuckle_joint" pos="0 0 0" axis="0 -1 0" range="0 0.75" actuatorfrcrange="-50 50"/> -->
                            <geom type="mesh" contype="0" conaffinity="0" group="1" density="0" rgba="0.898039 0.917647 0.929412 1" mesh="left_inner_knuckle"/>
                            <geom type="mesh" rgba="0.898039 0.917647 0.929412 1" mesh="left_inner_knuckle"/>
                          </body>
                          <site name="left_tcp" pos="7.0199E-05 -0.0004 -0.19142" euler="3.1415926 0 0"/>
                        </body>
                      </body>
                    </body>
                  </body>
                </body>
              </body>
            </body>
            <body name="right_arm_link_1" pos="-0.000119545 -0.290503 -0.00140256" quat="0.499931 0.500068 -0.500981 0.499018">
              <inertial pos="-0.0042142 0.02821 -0.0087788" quat="0.917781 -0.277115 0.0606681 0.277858" mass="0.42603" diaginertia="0.00144551 0.00137757 0.000823511"/>
              <joint name="right_arm_joint_1" pos="0 0 0" axis="0 0 1" range="-6.28144 6.28144" actuatorfrcrange="-50 50" damping="10" frictionloss="1"/>
              <geom type="mesh" contype="0" conaffinity="0" group="1" density="0" rgba="0.902 0.902 0.902 1" mesh="arm_link1"/>
              <geom type="mesh" rgba="0.902 0.902 0.902 1" mesh="arm_link1"/>
              <body name="right_arm_link_2" pos="0.00018849 4.00533e-05 -2.299e-07" quat="0.499144 -0.501901 -0.500968 -0.497978">
                <inertial pos="-3.3178e-05 -0.12849 0.026337" quat="0.447793 0.894132 -0.00224061 0.00218314" mass="0.56095" diaginertia="0.00319151 0.00311598 0.000980804"/>
                <joint name="right_arm_joint_2" pos="0 0 0" axis="0 0 1" range="-0.471687 3.59545" actuatorfrcrange="-50 50" damping="10" frictionloss="1"/>
                <geom type="mesh" contype="0" conaffinity="0" group="1" density="0" rgba="0.902 0.902 0.902 1" mesh="arm_link2"/>
                <geom type="mesh" rgba="0.902 0.902 0.902 1" mesh="arm_link2"/>
                <body name="right_arm_link_3" pos="0.000110741 -0.292526 -0.00168114" quat="0.498311 0.501795 -0.501074 0.498811">
                  <inertial pos="0.04223 -0.023258 -0.0096674" quat="0.883205 0.339803 0.323238 0.000542237" mass="0.44463" diaginertia="0.00133227 0.00119126 0.000780475"/>
                  <joint name="right_arm_joint_3" pos="0 0 0" axis="0 0 1" range="-7.81908 4.67748" actuatorfrcrange="-30 30" damping="5" frictionloss="1"/>
                  <geom type="mesh" contype="0" conaffinity="0" group="1" density="0" rgba="0.902 0.902 0.902 1" mesh="arm_link3"/>
                  <geom type="mesh" rgba="0.902 0.902 0.902 1" mesh="arm_link3"/>
                  <body name="right_arm_link_4" pos="0.052001 0.00080659 4.08215e-06" quat="0.00184333 -0.00270193 -0.708364 0.70584">
                    <inertial pos="0.067148 -0.10732 0.024479" quat="0.0654142 0.483317 -0.738663 0.465298" mass="0.52387" diaginertia="0.00288984 0.00282705 0.000894409"/>
                    <joint name="right_arm_joint_4" pos="0 0 0" axis="0 0 1" range="-3.2114 0.750476" actuatorfrcrange="-30 30" damping="5" frictionloss="1"/>
                    <geom type="mesh" contype="0" conaffinity="0" group="1" density="0" rgba="0.902 0.902 0.902 1" mesh="arm_link4"/>
                    <geom type="mesh" rgba="0.902 0.902 0.902 1" mesh="arm_link4"/>
                    <body name="right_arm_link_5" pos="0.0770178 -0.341838 -0.000191496" quat="0.500546 0.502664 -0.497603 0.499174">
                      <inertial pos="-0.00023397 0.036705 -0.080064" quat="0.981064 -0.19003 0.00637998 0.0369004" mass="0.18554" diaginertia="0.00099553 0.000988613 0.000247126"/>
                      <joint name="right_arm_joint_5" pos="0 0 0" axis="0 0 1" range="-7.8191 4.67748" actuatorfrcrange="-30 30" damping="5" frictionloss="1"/>
                      <geom type="mesh" contype="0" conaffinity="0" group="1" density="0" rgba="0.902 0.902 0.902 1" mesh="arm_link5"/>
                      <geom type="mesh" rgba="0.902 0.902 0.902 1" mesh="arm_link5"/>
                      <body name="right_arm_link_6" pos="0.000155265 -0.00361337 -6.4194e-05" quat="0.700798 0.713358 -0.0016632 0.000951125">
                        <inertial pos="0.058911 0.028469 0.0068428" quat="-0.188705 0.793535 0.166088 0.554173" mass="0.31344" diaginertia="0.000827892 0.000768871 0.000386708"/>
                        <joint name="right_arm_joint_6" pos="0 0 0" axis="0 0 1" range="-1.69122 2.81173" actuatorfrcrange="-20 20" damping="2" frictionloss="1"/>
                        <geom type="mesh" contype="0" conaffinity="0" group="1" density="0" rgba="0.902 0.902 0.902 1" mesh="arm_link6"/>
                        <geom type="mesh" rgba="0.902 0.902 0.902 1" mesh="arm_link6"/>
                        <body name="right_arm_link_7" pos="0.0770371 0.0959785 -0.00181105" quat="0.505361 0.494828 -0.494756 0.504947">
                          <inertial pos="0.00378125 -0.000524363 0.0171849" quat="0.0245617 0.720001 0.0325142 0.692776" mass="0.395374" diaginertia="0.000305869 0.000266043 0.000194474"/>
                          <joint name="right_arm_joint_7" pos="0 0 0" axis="0 0 -1" range="-6.24825 6.24825" actuatorfrcrange="-20 20" damping="2" frictionloss="1"/>
                          <geom type="mesh" contype="0" conaffinity="0" group="1" density="0" rgba="0.3922 0.3529 1 1" mesh="right_arm_link_7"/>
                          <geom type="mesh" rgba="0.3922 0.3529 1 1" mesh="right_arm_link_7"/>
                          <geom quat="1.32679e-06 1 0 0" type="mesh" contype="0" conaffinity="0" group="1" density="0" rgba="0.89804 0.91765 0.92941 1" mesh="gripper_base_link"/>
                          <geom quat="1.32679e-06 1 0 0" type="mesh" rgba="0.89804 0.91765 0.92941 1" mesh="gripper_base_link"/>
                          <body name="right_drive_gear" pos="0.0011556 -0.0121001 -0.036" quat="1.32679e-06 1 0 0">
                            <inertial pos="-3.30863e-05 0 1.19034e-05" quat="0.406662 0.578469 0.578469 0.406662" mass="0.000219454" diaginertia="2.46049e-09 1.69299e-09 1.68169e-09"/>
                            <!-- <joint name="right_drive_gear_joint" pos="0 0 0" axis="0 1 0" range="0 5.8469" actuatorfrcrange="-50 50"/> -->
                            <geom type="mesh" contype="0" conaffinity="0" group="1" density="0" rgba="1 1 1 1" mesh="drive_gear"/>
                            <geom type="mesh" rgba="1 1 1 1" mesh="drive_gear"/>
                          </body>
                          <body name="right_right_outer_knuckle" pos="0.03375 -0.0121001 -0.055535" quat="1.32679e-06 1 0 0">
                            <inertial pos="0.0101367 -0.0106013 0.026909" quat="0.744778 0.0907976 0.0929397 0.654541" mass="0.0201205" diaginertia="1.64045e-05 1.61602e-05 2.01288e-06"/>
                            <!-- <joint name="right_right_outer_knuckle_joint" pos="0 0 0" axis="0 1 0" range="0 0.75" actuatorfrcrange="-50 50"/> -->
                            <geom type="mesh" contype="0" conaffinity="0" group="1" density="0" rgba="1 1 1 1" mesh="right_outer_knuckle"/>
                            <geom type="mesh" rgba="1 1 1 1" mesh="right_outer_knuckle"/>
                            <body name="right_right_finger" pos="0.0185706 -0.0121 0.0778147">
                              <inertial pos="-0.0327727 -0.000698948 0.0346732" quat="0.981928 0.0388869 -0.181266 0.0380528" mass="0.036312" diaginertia="6.10124e-06 4.94402e-06 2.82504e-06"/>
                              <!-- <joint name="right_right_finger_joint" pos="0 0 0" axis="0 -1 0" range="0 0.75" actuatorfrcrange="-50 50"/> -->
                              <geom type="mesh" contype="0" conaffinity="0" group="1" density="0" rgba="0.898039 0.917647 0.929412 1" mesh="right_finger"/>
                              <geom type="mesh" rgba="0.898039 0.917647 0.929412 1" mesh="right_finger"/>
                            </body>
                          </body>
                          <body name="right_right_inner_knuckle" pos="0.007 0.00039977 -0.086606" quat="1.32679e-06 1 0 0">
                            <inertial pos="0.0165754 1.41152e-08 0.030873" quat="0.70183 0.0862093 0.086209 0.701833" mass="0.0178591" diaginertia="1.36612e-05 1.32419e-05 1.68573e-06"/>
                            <!-- <joint name="right_right_inner_knuckle_joint" pos="0 0 0" axis="0 1 0" range="0 0.75" actuatorfrcrange="-50 50"/> -->
                            <geom type="mesh" contype="0" conaffinity="0" group="1" density="0" rgba="0.898039 0.917647 0.929412 1" mesh="right_inner_knuckle"/>
                            <geom type="mesh" rgba="0.898039 0.917647 0.929412 1" mesh="right_inner_knuckle"/>
                          </body>
                          <body name="right_left_outer_knuckle" pos="-0.03375 -0.0146001 -0.055535" quat="1.32679e-06 1 0 0">
                            <inertial pos="-0.0187019 -0.0139951 0.0249289" quat="0.667096 -0.223958 -0.234709 0.670624" mass="0.0386243" diaginertia="3.29051e-05 2.86663e-05 7.92113e-06"/>
                            <!-- <joint name="right_left_outer_knuckle_joint" pos="0 0 0" axis="0 -1 0" range="0 0.75" actuatorfrcrange="-50 50"/> -->
                            <geom type="mesh" contype="0" conaffinity="0" group="1" density="0" rgba="1 1 1 1" mesh="left_outer_knuckle"/>
                            <geom type="mesh" rgba="1 1 1 1" mesh="left_outer_knuckle"/>
                            <body name="right_left_finger" pos="-0.0185764 -0.006 0.0778133">
                              <inertial pos="0.0368553 -0.00948093 0.0371392" quat="0.988534 0.0600377 0.131147 -0.044681" mass="0.0455798" diaginertia="7.86432e-06 6.42439e-06 3.39572e-06"/>
                              <!-- <joint name="right_left_finger_joint" pos="0 0 0" axis="0 1 0" range="0 0.75" actuatorfrcrange="-50 50"/> -->
                              <geom type="mesh" contype="0" conaffinity="0" group="1" density="0" rgba="0.898039 0.917647 0.929412 1" mesh="left_finger"/>
                              <geom type="mesh" rgba="0.898039 0.917647 0.929412 1" mesh="left_finger"/>
                            </body>
                          </body>
                          <body name="right_left_inner_knuckle" pos="-0.007 -0.0189002 -0.0866059" quat="1.32679e-06 1 0 0">
                            <inertial pos="-0.0251383 -0.0193 0.020239" quat="0.305321 0.637793 0.637793 0.305321" mass="0.0371734" diaginertia="2.84355e-05 1.87893e-05 1.22822e-05"/>
                            <!-- <joint name="right_left_inner_knuckle_joint" pos="0 0 0" axis="0 -1 0" range="0 0.75" actuatorfrcrange="-50 50"/> -->
                            <geom type="mesh" contype="0" conaffinity="0" group="1" density="0" rgba="0.898039 0.917647 0.929412 1" mesh="left_inner_knuckle"/>
                            <geom type="mesh" rgba="0.898039 0.917647 0.929412 1" mesh="left_inner_knuckle"/>
                          </body>
                          <site name="right_tcp" pos="7.0199E-05 -0.0004 -0.19142" euler="3.1415926 0 0"/>
                        </body>
                      </body>
                    </body>
                  </body>
                </body>
              </body>
            </body>
          </body>
        </body>
      </body>
    </body>
  </worldbody>

  <actuator>
    <!-- <general name="body_joint_1_ctrl" joint="body_joint_1" class="motor" ctrlrange="-500.059 1000.0944"/>
    <general name="body_joint_2_ctrl" joint="body_joint_2" class="motor" ctrlrange="-200.059 200.0944"/>
    <general name="body_joint_3_ctrl" joint="body_joint_3" class="motor" ctrlrange="-20.059 20.0944"/>
    <general name="head_joint_1_ctrl" joint="head_joint_1" class="motor" ctrlrange="-20.059 20.0944"/>
    <general name="head_joint_2_ctrl" joint="head_joint_2" class="motor" ctrlrange="-60.059 60.0944"/>
    <general name="left_arm_joint_1_ctrl" joint="left_arm_joint_1" class="size1" ctrlrange="-2.059 2.0944" />
    <general name="left_arm_joint_2_ctrl" joint="left_arm_joint_2" class="size1" ctrlrange="-2.059 2.0944" />
    <general name="left_arm_joint_3_ctrl" joint="left_arm_joint_3" class="size2" ctrlrange="-0.19198 3.927" />
    <general name="left_arm_joint_4_ctrl" joint="left_arm_joint_4" class="size2" ctrlrange="-0.19198 3.927" />
    <general name="left_arm_joint_5_ctrl" joint="left_arm_joint_5" class="size2" ctrlrange="-0.19198 3.927" />
    <general name="left_arm_joint_6_ctrl" joint="left_arm_joint_6" class="size3" ctrlrange="-1.69297 3.14159" />
    <general name="left_arm_joint_7_ctrl" joint="left_arm_joint_7" class="size3" ctrlrange="-1.69297 3.14159" />
    <general name="left_drive_gear_joint_ctrl" joint="left_drive_gear_joint" class="size3" ctrlrange="0 5.8469" />

    <general name="right_arm_joint_1_ctrl" joint="right_arm_joint_1" class="size1" ctrlrange="-2.059 2.0944" />
    <general name="right_arm_joint_2_ctrl" joint="right_arm_joint_2" class="size1" ctrlrange="-2.059 2.0944" />
    <general name="right_arm_joint_3_ctrl" joint="right_arm_joint_3" class="size2" ctrlrange="-0.19198 3.927" />
    <general name="right_arm_joint_4_ctrl" joint="right_arm_joint_4" class="size2" ctrlrange="-0.19198 3.927" />
    <general name="right_arm_joint_5_ctrl" joint="right_arm_joint_5" class="size2" ctrlrange="-0.19198 3.927" />
    <general name="right_arm_joint_6_ctrl" joint="right_arm_joint_6" class="size3" ctrlrange="-1.69297 3.14159" />
    <general name="right_arm_joint_7_ctrl" joint="right_arm_joint_7" class="size3" ctrlrange="-1.69297 3.14159" />
    <general name="right_drive_gear_joint_ctrl" joint="right_drive_gear_joint" class="size3" ctrlrange="0 5.8469" /> -->

    <!-- <position name="body_joint_1_ctrl" joint="body_joint_1" ctrlrange="-1.3788 0.50615" />
    <position name="body_joint_2_ctrl" joint="body_joint_2" ctrlrange="-0.50615 2.6005" />
    <position name="body_joint_3_ctrl" joint="body_joint_3" ctrlrange="-1.2915 1.2915" />
    <position name="head_joint_1_ctrl" joint="head_joint_1" ctrlrange="-1.553343034 1.553343034" />
    <position name="head_joint_2_ctrl" joint="head_joint_2" ctrlrange="-0.41887902 0.41887902" /> -->
    <!-- <position name="left_arm_joint_1_ctrl" joint="left_arm_joint_1" ctrlrange="-6.281439781188965 6.281439781188965" kp="4000" />
    <position name="left_arm_joint_2_ctrl" joint="left_arm_joint_2" ctrlrange="-0.47168713768005377 3.595448434753418" kp="4000" />
    <position name="left_arm_joint_3_ctrl" joint="left_arm_joint_3" ctrlrange="-7.818976819915772 4.67748266418457" kp="3000" />
    <position name="left_arm_joint_4_ctrl" joint="left_arm_joint_4" ctrlrange="-3.1064263031446933 0.7503646604156495" kp="3000" />
    <position name="left_arm_joint_5_ctrl" joint="left_arm_joint_5" ctrlrange="-7.820627630157471 4.677452146606445" kp="2000" />
    <position name="left_arm_joint_6_ctrl" joint="left_arm_joint_6" ctrlrange="-1.6912236213684082 2.872974157333374" kp="1000" />
    <position name="left_arm_joint_7_ctrl" joint="left_arm_joint_7" ctrlrange="-6.281439781188965 6.281439781188965" kp="1000" /> -->
    <!-- <position name="left_drive_gear_joint_ctrl" joint="left_drive_gear_joint" ctrlrange="0 5.8469" kp="1" dampratio="1.0" /> -->

    <!-- <position name="right_arm_joint_1_ctrl" joint="right_arm_joint_1" ctrlrange="-6.281439781188965 6.281439781188965" kp="4000" />
    <position name="right_arm_joint_2_ctrl" joint="right_arm_joint_2" ctrlrange="-0.47168713768005377 3.595448434753418" kp="4000" />
    <position name="right_arm_joint_3_ctrl" joint="right_arm_joint_3" ctrlrange="-7.819076478881836 4.67748266418457" kp="3000" />
    <position name="right_arm_joint_4_ctrl" joint="right_arm_joint_4" ctrlrange="-3.211403385605812 0.75047600189209" kp="3000" />
    <position name="right_arm_joint_5_ctrl" joint="right_arm_joint_5" ctrlrange="-7.81909936706543 4.6774769421386715" kp="2000" />
    <position name="right_arm_joint_6_ctrl" joint="right_arm_joint_6" ctrlrange="-1.6912236213684082 2.811725378036499" kp="1000" />
    <position name="right_arm_joint_7_ctrl" joint="right_arm_joint_7" ctrlrange="-6.248254776000977 6.248254776000977" kp="1000" /> -->
    <!-- <position name="right_drive_gear_joint_ctrl" joint="right_drive_gear_joint" ctrlrange="0 5.8469" kp="1" dampratio="1.0" /> -->

    <!-- <motor name="body_joint_1_ctrl" joint="body_joint_1" ctrlrange="-1.3788 0.50615" />
    <motor name="body_joint_2_ctrl" joint="body_joint_2" ctrlrange="-0.50615 2.6005" /> -->
    <!-- <motor name="body_joint_3_ctrl" joint="body_joint_3" ctrlrange="-1.2915 1.2915" /> -->
    <!-- <motor name="head_joint_1_ctrl" joint="head_joint_1" ctrlrange="-1.553343034 1.553343034" />
    <motor name="head_joint_2_ctrl" joint="head_joint_2" ctrlrange="-0.41887902 0.41887902" /> -->

    <motor name="left_arm_joint_1_ctrl" joint="left_arm_joint_1" ctrlrange="-6.281439781188965 6.281439781188965" />
    <motor name="left_arm_joint_2_ctrl" joint="left_arm_joint_2" ctrlrange="-0.47168713768005377 3.595448434753418" />
    <motor name="left_arm_joint_3_ctrl" joint="left_arm_joint_3" ctrlrange="-7.818976819915772 4.67748266418457" />
    <motor name="left_arm_joint_4_ctrl" joint="left_arm_joint_4" ctrlrange="-3.1064263031446933 0.7503646604156495" />
    <motor name="left_arm_joint_5_ctrl" joint="left_arm_joint_5" ctrlrange="-7.820627630157471 4.677452146606445" />
    <motor name="left_arm_joint_6_ctrl" joint="left_arm_joint_6" ctrlrange="-1.6912236213684082 2.872974157333374" />
    <motor name="left_arm_joint_7_ctrl" joint="left_arm_joint_7" ctrlrange="-6.281439781188965 6.281439781188965" />

    <motor name="right_arm_joint_1_ctrl" joint="right_arm_joint_1" ctrlrange="-6.281439781188965 6.281439781188965" />
    <motor name="right_arm_joint_2_ctrl" joint="right_arm_joint_2" ctrlrange="-0.47168713768005377 3.595448434753418" />
    <motor name="right_arm_joint_3_ctrl" joint="right_arm_joint_3" ctrlrange="-7.819076478881836 4.67748266418457" />
    <motor name="right_arm_joint_4_ctrl" joint="right_arm_joint_4" ctrlrange="-3.211403385605812 0.75047600189209" />
    <motor name="right_arm_joint_5_ctrl" joint="right_arm_joint_5" ctrlrange="-7.81909936706543 4.6774769421386715" />
    <motor name="right_arm_joint_6_ctrl" joint="right_arm_joint_6" ctrlrange="-1.6912236213684082 2.811725378036499" />
    <motor name="right_arm_joint_7_ctrl" joint="right_arm_joint_7" ctrlrange="-6.248254776000977 6.248254776000977" />
  </actuator>
  <!-- ctrl="0 0 0 0 0 0 0 0 0 0 0 0 0 0 0 0 0 0 0 0 0"  -->
  <!-- <keyframe>
    <key name="home" 
    qpos="-0.39 1.02 0 0 0   0.6265732 1.64933479 -1.2618717 -1.65806019 -6.30063725 1.58824956 0.32637656   0  0 0 0 0 0 0  -1.484266996383667 2.322235584259033 -1.3403406143188477 -2.110537052154541 -3.470266342163086 1.7113285064697266 0.9290168285369873 0 0 0 0 0 0 0" 
    time="0" 
    qvel="0 0 0 0 0 0 0 0 0 0 0 0 0 0 0 0 0 0 0 0 0 0 0 0 0 0 0 0 0 0 0 0 0"/>
  </keyframe> -->
  <custom>
    <!--  ctrl="0 0 0 -1.57079 0 1.57079 -0.7853"  -->
    <numeric name="init_pos" data="0.71145838  1.89922416 -1.49000406 -1.50572026 -6.282444    1.55580163 0.39406434 -1.40241504  2.20145106 -0.82001686 -1.50840473 -3.48541212 1.80923069  0.99399656"/>
    <!-- <numeric name="init_pos" data="0 0 0 0 0 0 0 0 0 0 0 0 0 0"/> -->
  
  </custom>

</mujoco>
