<?xml version="1.0"?>
<robot name="A2D">
  <mujoco>
    <compiler meshdir="./meshes" discardvisual="false"/>
  </mujoco>

  <link name="base_link">
    <inertial>
      <origin xyz="-0.0134486971267798 0.00152103941353612 -0.0320076754329413" rpy="0 0 0"/>
      <mass value="23.2085382238952"/>  <!-- 底盘质量约23.2kg -->
      <inertia
        ixx="0.386955641760608" ixy="0.000135417314593726" ixz="0.00669301645720665"
        iyy="0.366800407621218" iyz="0.000105713634260505" izz="0.546852919828475"/>
    </inertial>
    
    <visual>
      <origin xyz="0 0 0" rpy="0 0 0"/>
      <geometry>
        <mesh filename="package://meshes/base_link.STL"/>
      </geometry>
      <material name="">
        <color rgba="0.752941176470588 0.752941176470588 0.752941176470588 1"/>  <!-- 灰色 -->
      </material>
    </visual>
    
    <collision>
      <origin xyz="0 0 0" rpy="0 0 0"/>
      <geometry>
        <mesh filename="package://meshes/base_link.STL"/>
      </geometry>
    </collision>
  </link>

  <!-- 升降机构link：控制整体高度的部分 -->
  <link name="link_up_down_body">
    <inertial>
      <origin xyz="0.0338351537064605 -0.00248044044451858 0.000838431095422365" rpy="0 0 0"/>
      <mass value="3.26275452360108"/>
      <inertia
        ixx="0.0128301877197417" ixy="8.24967996575627E-06" ixz="1.38254543337324E-05"
        iyy="0.006104110250297" iyz="-7.99392548994692E-06" izz="0.0111721084996867"/>
    </inertial>
    
    <visual>
      <origin xyz="0 0 0" rpy="0 0 0"/>
      <geometry>
        <mesh filename="package://meshes/link_up_down_body.STL"/>
      </geometry>
      <material name="">
        <color rgba="0.752941176470588 0.752941176470588 0.752941176470588 1"/>
      </material>
    </visual>
    
    <collision>
      <origin xyz="0 0 0" rpy="0 0 0"/>
      <geometry>
        <mesh filename="package://meshes/link_up_down_body.STL"/>
      </geometry>
    </collision>
  </link>

  <!-- 升降关节：控制机器人整体高度，可上升30cm -->
  <joint name="joint_lift_body" type="prismatic">
    <origin xyz="0 0 0.6485" rpy="0 0 0"/>  <!-- 从底盘上方34.85cm处开始 -->
    <parent link="base_link"/>
    <child link="link_up_down_body"/>
    <axis xyz="0 0 1"/>                      <!-- 沿Z轴方向运动 -->
    <limit lower="0" upper="0.5" effort="1000" velocity="2.6100"/>  <!-- 升降范围0-30cm -->
  </joint>

  <!-- 身体俯仰link：可前后倾斜的躯干部分 -->
  <link name="link_pitch_body">
    <inertial>
      <origin xyz="0.193733558855111 -0.000484180179482319 -0.00124011422952511" rpy="0 0 0"/>
      <mass value="7.53199207979272"/>
      <inertia
        ixx="0.016546682835947" ixy="0.000274441382484697" ixz="0.00102757387076422"
        iyy="0.0445441227006132" iyz="-0.000236858278708531" izz="0.0402036337794082"/>
    </inertial>
    
    <visual>
      <origin xyz="0 0 0" rpy="3.14159 0 0"/>
      <geometry>
        <mesh filename="package://meshes/link_pitch_body.STL"/>
      </geometry>
      <material name="">
        <color rgba="0.752941176470588 0.752941176470588 0.752941176470588 1"/>
      </material>
    </visual>
    
    <collision>
      <origin xyz="0 0 0" rpy="3.14159 0 0"/>
      <geometry>
        <mesh filename="package://meshes/link_pitch_body.STL"/>
      </geometry>
    </collision>
  </link>

  <!-- 身体俯仰关节：控制机器人俯仰，可俯仰45度 -->
  <joint name="joint_body_pitch" type="revolute">
    <origin xyz="0.131 0 0" rpy="1.5708 -1.5708 0"/>  <!-- 从升降机构前方13.1cm处 -->
    <parent link="link_up_down_body"/>
    <child link="link_pitch_body"/>
    <axis xyz="0 0 -1"/>                              <!-- 绕Z轴负方向旋转 -->
    <limit lower="0" upper="1.047197551" effort="1000" velocity="2.6100"/>  <!-- 0-45度俯仰 -->
  </joint>

  <!-- 头部偏航link：可左右转动的头部 -->
  <link name="link_yaw_head">
    <inertial>
      <origin xyz="0.0446068140025754 0.00241753143645124 0.0528373754603559" rpy="0 0 0"/>
      <mass value="0.414342871921048"/>
      <inertia
        ixx="0.000158695728344024" ixy="-1.04590928109554E-06" ixz="-6.58530903139189E-06"
        iyy="0.000117742864399469" iyz="-2.65011299996072E-06" izz="0.000170947040827065"/>
    </inertial>
    
    <visual>
      <origin xyz="0 0 0" rpy="0 0 3.14159"/>
      <geometry>
        <mesh filename="package://meshes/link_yaw_head.STL"/>
      </geometry>
      <material name="">
        <color rgba="0.752941176470588 0.752941176470588 0.752941176470588 1"/>
      </material>
    </visual>
    
    <collision>
      <origin xyz="0 0 0" rpy="0 0 3.14159"/>
      <geometry>
        <mesh filename="package://meshes/link_yaw_head.STL"/>
      </geometry>
    </collision>
  </link>

  <!-- 头部偏航关节：控制头部左右转动，每边90度 -->
  <joint name="joint_head_yaw" type="fixed">
    <origin xyz="0.441 0 0" rpy="1.5708 0 1.5708"/>  <!-- 从躯干前方44.1cm处 -->
    <parent link="link_pitch_body"/>
    <child link="link_yaw_head"/>
    <axis xyz="0 0 1"/>                              <!-- 绕Z轴旋转 -->
    <limit lower="-1.5708" upper="1.5708" effort="50" velocity="1.0"/>  <!-- 左右各90度 -->
  </joint>

  <!-- 头部俯仰link：可上下点头的部分 -->
  <link name="link_pitch_head">
    <inertial>
      <origin xyz="0.0257009265816389 0.0316254080188787 -3.77390122592164E-05" rpy="0 0 0"/>
      <mass value="0.707063977171202"/>
      <inertia
        ixx="0.00205409595373573" ixy="0.000347730118005016" ixz="-2.13857752451204E-06"
        iyy="0.00200357281313449" iyz="5.16150600423908E-08" izz="0.00184999028444405"/>
    </inertial>
    
    <visual>
      <origin xyz="0 0 0" rpy="0 3.14159 0"/>
      <geometry>
        <mesh filename="package://meshes/link_pitch_head.STL"/>
      </geometry>
      <material name="">
        <color rgba="0.752941176470588 0.752941176470588 0.752941176470588 1"/>
      </material>
    </visual>
    
    <collision>
      <origin xyz="0 0 0" rpy="0 3.14159 0"/>
      <geometry>
        <mesh filename="package://meshes/link_pitch_head.STL"/>
      </geometry>
    </collision>
  </link>

  <!-- 头部俯仰关节：控制头部上下点头，每边45度 -->
  <joint name="joint_head_pitch" type="fixed">
    <origin xyz="-0.050238 0 0.060065" rpy="1.5708 0 0"/>
    <parent link="link_yaw_head"/>
    <child link="link_pitch_head"/>
    <axis xyz="0 0 1"/>
    <limit lower="-0.785398" upper="0.785398" effort="50" velocity="1.0"/>  <!-- 上下各45度 -->
  </joint>

  <!-- 机械臂link：固定在躯干上的机械臂 -->
  <link name="link_arm"/>

  <!-- 机械臂固定关节：将机械臂固定在躯干上 -->
  <joint name="joint_arm_mount" type="fixed">
    <origin xyz="0.305 0 0" rpy="-1.5708 0 -1.5708"/>  <!-- 从躯干前方30.5cm处固定 -->
    <parent link="link_pitch_body"/>
    <child link="link_arm"/>
    <axis xyz="0 0 1"/>
  </joint>

  <!-- 左臂固定关节：将左臂固定在机器人躯干上 -->
  <joint name="joint_left_arm_mount" type="fixed">
    <origin xyz="0 0.025 0" rpy="-1.5708 0 0"/>  <!-- 从link_arm向左偏移2.5cm -->
    <parent link="link_arm"/>
    <child link="base_link_l"/>
  </joint>

  <!-- 右臂固定关节：将右臂固定在机器人躯干上 -->
  <joint name="joint_right_arm_mount" type="fixed">
    <origin xyz="0 -0.025 0" rpy="1.5708 -3.14159 0"/>  <!-- 从link_arm向右偏移2.5cm -->
    <parent link="link_arm"/>
    <child link="base_link_r"/>
  </joint>

  <!-- 左臂的所有link和joint定义 -->
  <link
    name="base_link_l">
    <inertial>
      <origin
        xyz="0.00020641 -0.00057488 0.034396"
        rpy="0 0 0" />
      <mass
        value="0.37595" />
      <inertia
        ixx="0.00024335"
        ixy="1.2188E-06"
        ixz="2.4281E-06"
        iyy="0.00024039"
        iyz="-6.6932E-06"
        izz="0.00032195" />
    </inertial>
    <visual>
      <origin
        xyz="0 0 0"
        rpy="0 0 0" />
      <geometry>
        <mesh
          filename="package://meshes/base_link_l.STL" />
      </geometry>
      <material
        name="">
        <color
          rgba="0.75294 0.75294 0.75294 1" />
      </material>
    </visual>
    <collision>
      <origin
        xyz="0 0 0"
        rpy="0 0 0" />
      <geometry>
        <mesh
          filename="package://meshes/base_link_l.STL" />
      </geometry>
    </collision>
  </link>
  <link
    name="Link1_l">
    <inertial>
      <origin
        xyz="-0.0014596 0.00049476 0.017089"
        rpy="0 0 0" />
      <mass
        value="0.43694" />
      <inertia
        ixx="0.00061894"
        ixy="-6.6923E-06"
        ixz="3.492E-06"
        iyy="0.00054909"
        iyz="1.2223E-06"
        izz="0.00026663" />
    </inertial>
    <visual>
      <origin
        xyz="0 0 0"
        rpy="0 0 0" />
      <geometry>
        <mesh
          filename="package://meshes/Link1_l.STL" />
      </geometry>
      <material
        name="">
        <color
          rgba="0.75294 0.75294 0.75294 1" />
      </material>
    </visual>
    <collision>
      <origin
        xyz="0 0 0"
        rpy="0 0 0" />
      <geometry>
        <mesh
          filename="package://meshes/Link1_l.STL" />
      </geometry>
    </collision>
  </link>
  <joint
    name="left_arm_joint1"
    type="revolute">
    <origin
      xyz="0 0 0.188"
      rpy="3.1416 0 0" />
    <parent
      link="base_link_l" />
    <child
      link="Link1_l" />
    <axis
      xyz="0 0 -1" />
    <limit
      lower="-3.14"
      upper="3.14"
      effort="60"
      velocity="3.14" />
  </joint>
  <link
    name="Link2_l">
    <inertial>
      <origin
        xyz="-0.00043013 0.088101 -0.0065021"
        rpy="0 0 0" />
      <mass
        value="0.31992" />
      <inertia
        ixx="0.00033101"
        ixy="-4.1377E-06"
        ixz="9.5154E-07"
        iyy="0.00022098"
        iyz="-4.8041E-05"
        izz="0.00031472" />
    </inertial>
    <visual>
      <origin
        xyz="0 0 0"
        rpy="0 0 0" />
      <geometry>
        <mesh
          filename="package://meshes/Link2_l.STL" />
      </geometry>
      <material
        name="">
        <color
          rgba="0.75294 0.75294 0.75294 1" />
      </material>
    </visual>
    <collision>
      <origin
        xyz="0 0 0"
        rpy="0 0 0" />
      <geometry>
        <mesh
          filename="package://meshes/Link2_l.STL" />
      </geometry>
    </collision>
  </link>
  <joint
    name="left_arm_joint2"
    type="revolute">
    <origin
      xyz="0 0 0"
      rpy="-1.5708 0 -1.5708" />
    <parent
      link="Link1_l" />
    <child
      link="Link2_l" />
    <axis
      xyz="0 0 -1" />
    <limit
      lower="-2.35619449"
      upper="2.35619449"
      effort="60"
      velocity="3.14" />
  </joint>
  <link
    name="Link3_l">
    <inertial>
      <origin
        xyz="0.00022593 0.0010417 0.034985"
        rpy="0 0 0" />
      <mass
        value="0.35545" />
      <inertia
        ixx="0.00081056"
        ixy="-2.4265E-06"
        ixz="9.353E-07"
        iyy="0.00083336"
        iyz="3.8681E-06"
        izz="0.00017128" />
    </inertial>
    <visual>
      <origin
        xyz="0 0 0"
        rpy="0 0 0" />
      <geometry>
        <mesh
          filename="package://meshes/Link3_l.STL" />
      </geometry>
      <material
        name="">
        <color
          rgba="0.75294 0.75294 0.75294 1" />
      </material>
    </visual>
    <collision>
      <origin
        xyz="0 0 0"
        rpy="0 0 0" />
      <geometry>
        <mesh
          filename="package://meshes/Link3_l.STL" />
      </geometry>
    </collision>
  </link>
  <joint
    name="left_arm_joint3"
    type="revolute">
    <origin
      xyz="0 0.305 0"
      rpy="1.5708 1.5708 0" />
    <parent
      link="Link2_l" />
    <child
      link="Link3_l" />
    <axis
      xyz="0 0 -1" />
    <limit
      lower="-3.14"
      upper="3.14"
      effort="60"
      velocity="3.14" />
  </joint>
  <link
    name="Link4_l">
    <inertial>
      <origin
        xyz="2.1713E-06 0.071943 -0.0054645"
        rpy="0 0 0" />
      <mass
        value="0.1848" />
      <inertia
        ixx="0.00014344"
        ixy="-1.7659E-08"
        ixz="-4.6234E-09"
        iyy="9.0443E-05"
        iyz="-2.1918E-05"
        izz="0.00013811" />
    </inertial>
    <visual>
      <origin
        xyz="0 0 0"
        rpy="0 0 0" />
      <geometry>
        <mesh
          filename="package://meshes/Link4_l.STL" />
      </geometry>
      <material
        name="">
        <color
          rgba="0.75294 0.75294 0.75294 1" />
      </material>
    </visual>
    <collision>
      <origin
        xyz="0 0 0"
        rpy="0 0 0" />
      <geometry>
        <mesh
          filename="package://meshes/Link4_l.STL" />
      </geometry>
    </collision>
  </link>
  <joint
    name="left_arm_joint4"
    type="revolute">
    <origin
      xyz="0 0 0"
      rpy="-1.5708 0 0" />
    <parent
      link="Link3_l" />
    <child
      link="Link4_l" />
    <axis
      xyz="0 0 -1" />
    <limit
      lower="-2.35619449"
      upper="2.35619449"
      effort="60"
      velocity="3.14" />
  </joint>
  <link
    name="Link5_l">
    <inertial>
      <origin
        xyz="-7.6715E-07 -6.7798E-05 -0.012879"
        rpy="0 0 0" />
      <mass
        value="0.1775" />
      <inertia
        ixx="0.00012838"
        ixy="1.6718E-09"
        ixz="6.959E-09"
        iyy="0.00013741"
        iyz="3.1692E-07"
        izz="6.2102E-05" />
    </inertial>
    <visual>
      <origin
        xyz="0 0 0"
        rpy="0 0 0" />
      <geometry>
        <mesh
          filename="package://meshes/Link5_l.STL" />
      </geometry>
      <material
        name="">
        <color
          rgba="0.75294 0.75294 0.75294 1" />
      </material>
    </visual>
    <collision>
      <origin
        xyz="0 0 0"
        rpy="0 0 0" />
      <geometry>
        <mesh
          filename="package://meshes/Link5_l.STL" />
      </geometry>
    </collision>
  </link>
  <joint
    name="left_arm_joint5"
    type="revolute">
    <origin
      xyz="0 0.1975 0"
      rpy="1.5708 0 -3.1416" />
    <parent
      link="Link4_l" />
    <child
      link="Link5_l" />
    <axis
      xyz="0 0 1" />
    <limit
      lower="-3.14"
      upper="3.14"
      effort="30"
      velocity="3.14" />
  </joint>
  <link
    name="Link6_l">
    <inertial>
      <origin
        xyz="2.2696E-06 -0.10227 -0.0029117"
        rpy="0 0 0" />
      <mass
        value="0.17825" />
      <inertia
        ixx="0.00013761"
        ixy="5.1473E-09"
        ixz="6.9927E-09"
        iyy="8.0777E-05"
        iyz="2.0192E-05"
        izz="0.00012814" />
    </inertial>
    <visual>
      <origin
        xyz="0 0 0"
        rpy="0 0 0" />
      <geometry>
        <mesh
          filename="package://meshes/Link6_l.STL" />
      </geometry>
      <material
        name="">
        <color
          rgba="0.75294 0.75294 0.75294 1" />
      </material>
    </visual>
    <collision>
      <origin
        xyz="0 0 0"
        rpy="0 0 0" />
      <geometry>
        <mesh
          filename="package://meshes/Link6_l.STL" />
      </geometry>
    </collision>
  </link>
  <joint
    name="left_arm_joint6"
    type="revolute">
    <origin
      xyz="0 0 0"
      rpy="-1.5708 0 3.1416" />
    <parent
      link="Link5_l" />
    <child
      link="Link6_l" />
    <axis
      xyz="0 0 -1" />
    <limit
      lower="-2.35619449"
      upper="2.35619449"
      effort="30"
      velocity="3.14" />
  </joint>
  <link
    name="Link7_l">
    <inertial>
      <origin
        xyz="-0.00025629 9.064E-06 -0.017205"
        rpy="0 0 0" />
      <mass
        value="0.06158" />
      <inertia
        ixx="1.8213E-05"
        ixy="-8.6954E-08"
        ixz="1.0858E-07"
        iyy="1.8374E-05"
        iyz="3.2442E-08"
        izz="2.8547E-05" />
    </inertial>
    <visual>
      <origin
        xyz="0 0 0"
        rpy="0 0 0" />
      <geometry>
        <mesh
          filename="package://meshes/Link7_l.STL" />
      </geometry>
      <material
        name="">
        <color
          rgba="0.75294 0.75294 0.75294 1" />
      </material>
    </visual>
    <collision>
      <origin
        xyz="0 0 0"
        rpy="0 0 0" />
      <geometry>
        <mesh
          filename="package://meshes/Link7_l.STL" />
      </geometry>
    </collision>
  </link>
  <joint
    name="left_arm_joint7"
    type="revolute">
    <origin
      xyz="0 -0.181 0"
      rpy="-1.5708 0 -3.1416" />
    <parent
      link="Link6_l" />
    <child
      link="Link7_l" />
    <axis
      xyz="0 0 1" />
    <limit
      lower="-6.28"
      upper="6.28"
      effort="30"
      velocity="3.14" />
  </joint>

  <joint
    name="Joint_hand_l"
    type="fixed">
    <origin
      xyz="0 0 0"
      rpy="0 1.5708 -1.5708" />
    <parent
      link="Link7_l" />
    <child
      link="left_finger_base" />
    <axis
      xyz="0 0 0" />
  </joint>

  <!-- 右臂的所有link和joint定义 -->
  <link
    name="base_link_r">
    <inertial>
      <origin
        xyz="0.00020641 -0.00057488 0.034396"
        rpy="0 0 0" />
      <mass
        value="0.37595" />
      <inertia
        ixx="0.00024335"
        ixy="1.2188E-06"
        ixz="2.4281E-06"
        iyy="0.00024039"
        iyz="-6.6932E-06"
        izz="0.00032195" />
    </inertial>
    <visual>
      <origin
        xyz="0 0 0"
        rpy="0 0 0" />
      <geometry>
        <mesh
          filename="package://meshes/base_link_r.STL" />
      </geometry>
      <material
        name="">
        <color
          rgba="0.75294 0.75294 0.75294 1" />
      </material>
    </visual>
    <collision>
      <origin
        xyz="0 0 0"
        rpy="0 0 0" />
      <geometry>
        <mesh
          filename="package://meshes/base_link_r.STL" />
      </geometry>
    </collision>
  </link>
  <link
    name="Link1_r">
    <inertial>
      <origin
        xyz="0.0013193 0.00016098 0.018211"
        rpy="0 0 0" />
      <mass
        value="0.48414" />
      <inertia
        ixx="0.000726"
        ixy="2.4165E-06"
        ixz="-7.7713E-06"
        iyy="0.00066689"
        iyz="1.2143E-06"
        izz="0.00028434" />
    </inertial>
    <visual>
      <origin
        xyz="0 0 0"
        rpy="0 0 0" />
      <geometry>
        <mesh
          filename="package://meshes/Link1_r.STL" />
      </geometry>
      <material
        name="">
        <color
          rgba="0.75294 0.75294 0.75294 1" />
      </material>
    </visual>
    <collision>
      <origin
        xyz="0 0 0"
        rpy="0 0 0" />
      <geometry>
        <mesh
          filename="package://meshes/Link1_r.STL" />
      </geometry>
    </collision>
  </link>
  <joint
    name="right_arm_joint1"
    type="revolute">
    <origin
      xyz="0 0 0.188"
      rpy="-3.1416 0 0" />
    <parent
      link="base_link_r" />
    <child
      link="Link1_r" />
    <axis
      xyz="0 0 -1" />
    <limit
      lower="-3.14"
      upper="3.14"
      effort="60"
      velocity="3.14" />
  </joint>
  <link
    name="Link2_r">
    <inertial>
      <origin
        xyz="0.00012037 -0.088102 -0.0062668"
        rpy="0 0 0" />
      <mass
        value="0.31993" />
      <inertia
        ixx="0.00033251"
        ixy="-1.2043E-06"
        ixz="-5.3938E-07"
        iyy="0.00022098"
        iyz="4.5816E-05"
        izz="0.00031325" />
    </inertial>
    <visual>
      <origin
        xyz="0 0 0"
        rpy="0 0 0" />
      <geometry>
        <mesh
          filename="package://meshes/Link2_r.STL" />
      </geometry>
      <material
        name="">
        <color
          rgba="0.75294 0.75294 0.75294 1" />
      </material>
    </visual>
    <collision>
      <origin
        xyz="0 0 0"
        rpy="0 0 0" />
      <geometry>
        <mesh
          filename="package://meshes/Link2_r.STL" />
      </geometry>
    </collision>
  </link>
  <joint
    name="right_arm_joint2"
    type="revolute">
    <origin
      xyz="0 0 0"
      rpy="1.5708 0 -1.5708" />
    <parent
      link="Link1_r" />
    <child
      link="Link2_r" />
    <axis
      xyz="0 0 -1" />
    <limit
      lower="-2.35619449"
      upper="2.35619449"
      effort="60"
      velocity="3.14" />
  </joint>
  <link
    name="Link3_r">
    <inertial>
      <origin
        xyz="-3.7545E-06 -0.00012549 -0.035846"
        rpy="0 0 0" />
      <mass
        value="0.34932" />
      <inertia
        ixx="0.00084957"
        ixy="-6.2047E-11"
        ixz="1.3496E-08"
        iyy="0.00082652"
        iyz="2.8949E-07"
        izz="0.00021145" />
    </inertial>
    <visual>
      <origin
        xyz="0 0 0"
        rpy="0 0 0" />
      <geometry>
        <mesh
          filename="package://meshes/Link3_r.STL" />
      </geometry>
      <material
        name="">
        <color
          rgba="0.75294 0.75294 0.75294 1" />
      </material>
    </visual>
    <collision>
      <origin
        xyz="0 0 0"
        rpy="0 0 0" />
      <geometry>
        <mesh
          filename="package://meshes/Link3_r.STL" />
      </geometry>
    </collision>
  </link>
  <joint
    name="right_arm_joint3"
    type="revolute">
    <origin
      xyz="0 -0.305 0"
      rpy="1.5708 1.5708 0" />
    <parent
      link="Link2_r" />
    <child
      link="Link3_r" />
    <axis
      xyz="0 0 1" />
    <limit
      lower="-3.14"
      upper="3.14"
      effort="60"
      velocity="3.14" />
  </joint>
  <link
    name="Link4_r">
    <inertial>
      <origin
        xyz="1.9102E-06 0.071943 -0.0054646"
        rpy="0 0 0" />
      <mass
        value="0.1848" />
      <inertia
        ixx="0.00014343"
        ixy="-1.7316E-08"
        ixz="-3.4456E-09"
        iyy="9.0442E-05"
        iyz="-2.1917E-05"
        izz="0.0001381" />
    </inertial>
    <visual>
      <origin
        xyz="0 0 0"
        rpy="0 0 0" />
      <geometry>
        <mesh
          filename="package://meshes/Link4_r.STL" />
      </geometry>
      <material
        name="">
        <color
          rgba="0.75294 0.75294 0.75294 1" />
      </material>
    </visual>
    <collision>
      <origin
        xyz="0 0 0"
        rpy="0 0 0" />
      <geometry>
        <mesh
          filename="package://meshes/Link4_r.STL" />
      </geometry>
    </collision>
  </link>
  <joint
    name="right_arm_joint4"
    type="revolute">
    <origin
      xyz="0 0 0"
      rpy="1.5708 0 -3.1416" />
    <parent
      link="Link3_r" />
    <child
      link="Link4_r" />
    <axis
      xyz="0 0 -1" />
    <limit
      lower="-2.35619449"
      upper="2.35619449"
      effort="60"
      velocity="3.14" />
  </joint>
  <link
    name="Link5_r">
    <inertial>
      <origin
        xyz="4.0146E-06 -6.7798E-05 -0.012877"
        rpy="0 0 0" />
      <mass
        value="0.1775" />
      <inertia
        ixx="0.00012838"
        ixy="-3.4874E-09"
        ixz="6.9591E-09"
        iyy="0.00013741"
        iyz="3.1477E-07"
        izz="6.2102E-05" />
    </inertial>
    <visual>
      <origin
        xyz="0 0 0"
        rpy="0 0 0" />
      <geometry>
        <mesh
          filename="package://meshes/Link5_r.STL" />
      </geometry>
      <material
        name="">
        <color
          rgba="0.75294 0.75294 0.75294 1" />
      </material>
    </visual>
    <collision>
      <origin
        xyz="0 0 0"
        rpy="0 0 0" />
      <geometry>
        <mesh
          filename="package://meshes/Link5_r.STL" />
      </geometry>
    </collision>
  </link>
  <joint
    name="right_arm_joint5"
    type="revolute">
    <origin
      xyz="0 0.1975 0"
      rpy="1.5708 0 -3.1416" />
    <parent
      link="Link4_r" />
    <child
      link="Link5_r" />
    <axis
      xyz="0 0 1" />
    <limit
      lower="-3.14"
      upper="3.14"
      effort="30"
      velocity="3.14" />
  </joint>
  <link
    name="Link6_r">
    <inertial>
      <origin
        xyz="-2.4946E-06 -0.10227 -0.0029098"
        rpy="0 0 0" />
      <mass
        value="0.17825" />
      <inertia
        ixx="0.00013761"
        ixy="-2.7933E-11"
        ixz="6.9889E-09"
        iyy="8.0777E-05"
        iyz="2.0194E-05"
        izz="0.00012814" />
    </inertial>
    <visual>
      <origin
        xyz="0 0 0"
        rpy="0 0 0" />
      <geometry>
        <mesh
          filename="package://meshes/Link6_r.STL" />
      </geometry>
      <material
        name="">
        <color
          rgba="0.75294 0.75294 0.75294 1" />
      </material>
    </visual>
    <collision>
      <origin
        xyz="0 0 0"
        rpy="0 0 0" />
      <geometry>
        <mesh
          filename="package://meshes/Link6_r.STL" />
      </geometry>
    </collision>
  </link>
  <joint
    name="right_arm_joint6"
    type="revolute">
    <origin
      xyz="0 0 0"
      rpy="-1.5708 0 3.1416" />
    <parent
      link="Link5_r" />
    <child
      link="Link6_r" />
    <axis
      xyz="0 0 -1" />
    <limit
      lower="-2.35619449"
      upper="2.35619449"
      effort="30"
      velocity="3.14" />
  </joint>
  <link
    name="Link7_r">
    <inertial>
      <origin
        xyz="0.0002265 0.00012031 -0.017205"
        rpy="0 0 0" />
      <mass
        value="0.06158" />
      <inertia
        ixx="1.8328E-05"
        ixy="-1.1354E-07"
        ixz="-7.7825E-08"
        iyy="1.8259E-05"
        iyz="-8.2338E-08"
        izz="2.8547E-05" />
    </inertial>
    <visual>
      <origin
        xyz="0 0 0"
        rpy="0 0 0" />
      <geometry>
        <mesh
          filename="package://meshes/Link7_r.STL" />
      </geometry>
      <material
        name="">
        <color
          rgba="0.75294 0.75294 0.75294 1" />
      </material>
    </visual>
    <collision>
      <origin
        xyz="0 0 0"
        rpy="0 0 0" />
      <geometry>
        <mesh
          filename="package://meshes/Link7_r.STL" />
      </geometry>
    </collision>
  </link>


  <joint
    name="right_arm_joint7"
    type="revolute">
    <origin
      xyz="0 -0.181 0"
      rpy="-1.5708 0 3.1416" />
    <parent
      link="Link6_r" />
    <child
      link="Link7_r" />
    <axis
      xyz="0 0 1" />
    <limit
      lower="-3.14"
      upper="3.14"
      effort="30"
      velocity="3.14" />
  </joint>

  <joint
    name="Joint_hand_r"
    type="fixed">
    <origin
      xyz="0 0 0"
      rpy="0 1.5708 -1.5708" />
    <parent
      link="Link7_r" />
    <child
      link="right_finger_base" />
    <axis
      xyz="0 0 0" />
  </joint>
  <link
    name="right_finger_base">
    <inertial>
      <origin
        xyz="0.0282680334155116 -0.00155312878370573 0.0090688183026775"
        rpy="0 0 0" />
      <mass
        value="0.0410424762542632" />
      <inertia
        ixx="1.67808110422422E-05"
        ixy="-1.38161155616436E-06"
        ixz="2.77639403016102E-07"
        iyy="1.59956087599769E-05"
        iyz="-2.84757118052629E-07"
        izz="2.62608804201258E-05" />
    </inertial>
    <visual>
      <origin
        xyz="0 0 0"
        rpy="0 0 0" />
      <geometry>
        <mesh
          filename="package://meshes/right_base_link.STL" />
      </geometry>
      <material
        name="">
        <color
          rgba="1 1 1 1" />
      </material>
    </visual>
    <collision>
      <origin
        xyz="0 0 0"
        rpy="0 0 0" />
      <geometry>
        <mesh
          filename="package://meshes/right_base_link.STL" />
      </geometry>
    </collision>
  </link>
  <link
    name="right_ff_proximal_link">
    <inertial>
      <origin
        xyz="-0.015386 -0.0066062 -0.0079647"
        rpy="0 0 0" />
      <mass
        value="0.0018523" />
      <inertia
        ixx="8.5863E-08"
        ixy="-4.71E-09"
        ixz="-4.397E-08"
        iyy="1.886E-07"
        iyz="-2.9657E-09"
        izz="1.808E-07" />
    </inertial>
    <visual>
      <origin
        xyz="0 0 0"
        rpy="0 0 0" />
      <geometry>
        <mesh
          filename="package://meshes/right_ff_proximal_link.STL" />
      </geometry>
      <material
        name="">
        <color
          rgba="1 1 1 1" />
      </material>
    </visual>
    <collision>
      <origin
        xyz="0 0 0"
        rpy="0 0 0" />
      <geometry>
        <mesh
          filename="package://meshes/right_ff_proximal_link.STL" />
      </geometry>
    </collision>
  </link>
  <joint
    name="right_ff_proximal_joint"
    type="revolute">
    <origin
      xyz="-0.11139 -0.034646 0.0057572"
      rpy="0 0 0" />
    <parent
      link="right_finger_base" />
    <child
      link="right_ff_proximal_link" />
    <axis
      xyz="0 1 0" />
    <limit
      lower="-1.23"
      upper="0.34"
      effort="50"
      velocity="1" />
  </joint>
  <link
    name="right_ff_distal_link">
    <inertial>
      <origin
        xyz="-0.0136744559671081 -0.00546355961032156 -0.0194579532929323"
        rpy="0 0 0" />
      <mass
        value="0.00411870576106074" />
      <inertia
        ixx="3.84711901595296E-07"
        ixy="6.16480172234882E-09"
        ixz="-2.5005841513438E-07"
        iyy="5.74190965189268E-07"
        iyz="6.30974065938001E-09"
        izz="2.65068505295533E-07" />
    </inertial>
    <visual>
      <origin
        xyz="0 0 0"
        rpy="0 0 0" />
      <geometry>
        <mesh
          filename="package://meshes/right_ff_distal_link.STL" />
      </geometry>
      <material
        name="">
        <color
          rgba="1 1 1 1" />
      </material>
    </visual>
    <collision>
      <origin
        xyz="0 0 0"
        rpy="0 0 0" />
      <geometry>
        <mesh
          filename="package://meshes/right_ff_distal_link.STL" />
      </geometry>
    </collision>
  </link>
  <joint
    name="right_ff_distal_joint"
    type="revolute">
    <origin
      xyz="-0.034906 -0.0015559 -0.0083266"
      rpy="0 0 0" />
    <parent
      link="right_ff_proximal_link" />
    <child
      link="right_ff_distal_link" />
    <axis
      xyz="0 1 0" />
    <limit
      lower="-1.23"
      upper="0.34"
      effort="50"
      velocity="1" />
    <mimic
      joint="right_ff_proximal_joint"
      multiplier="1"
      offset="0" />
  </joint>
  <link
    name="right_lf_proximal_link">
    <inertial>
      <origin
        xyz="-0.0146092609512682 -0.0055508873917868 -0.00670762165904373"
        rpy="0 0 0" />
      <mass
        value="0.00164259183850072" />
      <inertia
        ixx="7.83650178895857E-08"
        ixy="4.1832976450397E-09"
        ixz="-3.3038131625674E-08"
        iyy="1.37775200510857E-07"
        iyz="3.38529940940638E-09"
        izz="1.31770538978944E-07" />
    </inertial>
    <visual>
      <origin
        xyz="0 0 0"
        rpy="0 0 0" />
      <geometry>
        <mesh
          filename="package://meshes/right_lf_proximal_link.STL" />
      </geometry>
      <material
        name="">
        <color
          rgba="1 1 1 1" />
      </material>
    </visual>
    <collision>
      <origin
        xyz="0 0 0"
        rpy="0 0 0" />
      <geometry>
        <mesh
          filename="package://meshes/right_lf_proximal_link.STL" />
      </geometry>
    </collision>
  </link>
  <joint
    name="right_lf_proximal_joint"
    type="revolute">
    <origin
      xyz="-0.10962 0.025044 0.014795"
      rpy="0 0 0" />
    <parent
      link="right_finger_base" />
    <child
      link="right_lf_proximal_link" />
    <axis
      xyz="0 1 0" />
    <limit
      lower="-1.23"
      upper="0.34"
      effort="50"
      velocity="1" />
  </joint>
  <link
    name="right_lf_distal_link">
    <inertial>
      <origin
        xyz="-0.00921516331063749 -0.00657933694076938 -0.0137060475387422"
        rpy="0 0 0" />
      <mass
        value="0.00258549281540904" />
      <inertia
        ixx="1.24448167729541E-07"
        ixy="-7.90147373548682E-10"
        ixz="-5.47338391191158E-08"
        iyy="1.5333214661181E-07"
        iyz="4.20352585186048E-10"
        izz="7.16963433808903E-08" />
    </inertial>
    <visual>
      <origin
        xyz="0 0 0"
        rpy="0 0 0" />
      <geometry>
        <mesh
          filename="package://meshes/right_lf_distal_link.STL" />
      </geometry>
      <material
        name="">
        <color
          rgba="1 1 1 1" />
      </material>
    </visual>
    <collision>
      <origin
        xyz="0 0 0"
        rpy="0 0 0" />
      <geometry>
        <mesh
          filename="package://meshes/right_lf_distal_link.STL" />
      </geometry>
    </collision>
  </link>
  <joint
    name="right_lf_distal_joint"
    type="revolute">
    <origin
      xyz="-0.030661 0.0028404 -0.0084539"
      rpy="0 0 0" />
    <parent
      link="right_lf_proximal_link" />
    <child
      link="right_lf_distal_link" />
    <axis
      xyz="0 1 0" />
    <limit
      lower="-1.23"
      upper="0.34"
      effort="50"
      velocity="1" />
    <mimic
      joint="right_lf_proximal_joint"
      multiplier="1"
      offset="0" />
  </joint>
  <link
    name="right_mf_proximal_link">
    <inertial>
      <origin
        xyz="-0.0177059315083575 -0.0068574882263558 -0.00949570438060691"
        rpy="0 0 0" />
      <mass
        value="0.00222072837890887" />
      <inertia
        ixx="1.18469806234159E-07"
        ixy="-2.169203589617E-09"
        ixz="-7.66611865960727E-08"
        iyy="2.82300078965434E-07"
        iyz="-1.01552906952095E-09"
        izz="2.55439925655879E-07" />
    </inertial>
    <visual>
      <origin
        xyz="0 0 0"
        rpy="0 0 0" />
      <geometry>
        <mesh
          filename="package://meshes/right_mf_proximal_link.STL" />
      </geometry>
      <material
        name="">
        <color
          rgba="1 1 1 1" />
      </material>
    </visual>
    <collision>
      <origin
        xyz="0 0 0"
        rpy="0 0 0" />
      <geometry>
        <mesh
          filename="package://meshes/right_mf_proximal_link.STL" />
      </geometry>
    </collision>
  </link>
  <joint
    name="right_mf_proximal_joint"
    type="revolute">
    <origin
      xyz="-0.11472 -0.015366 0.013131"
      rpy="0 0 0" />
    <parent
      link="right_finger_base" />
    <child
      link="right_mf_proximal_link" />
    <axis
      xyz="0 1 0" />
    <limit
      lower="-1.23"
      upper="0.34"
      effort="50"
      velocity="1" />
  </joint>
  <link
    name="right_mf_distal_link">
    <inertial>
      <origin
        xyz="-0.0143449599107263 -0.0068015916660648 -0.0187410189605281"
        rpy="0 0 0" />
      <mass
        value="0.00411871594900483" />
      <inertia
        ixx="3.77681695290248E-07"
        ixy="-2.6050362803194E-09"
        ixz="-2.51747092435786E-07"
        iyy="5.74182941173459E-07"
        iyz="-3.33591966287697E-09"
        izz="2.72077516511856E-07" />
    </inertial>
    <visual>
      <origin
        xyz="0 0 0"
        rpy="0 0 0" />
      <geometry>
        <mesh
          filename="package://meshes/right_mf_distal_link.STL" />
      </geometry>
      <material
        name="">
        <color
          rgba="1 1 1 1" />
      </material>
    </visual>
    <collision>
      <origin
        xyz="0 0 0"
        rpy="0 0 0" />
      <geometry>
        <mesh
          filename="package://meshes/right_mf_distal_link.STL" />
      </geometry>
    </collision>
  </link>
  <joint
    name="right_mf_distal_joint"
    type="revolute">
    <origin
      xyz="-0.039577 -2.2566E-05 -0.010735"
      rpy="0 0 0" />
    <parent
      link="right_mf_proximal_link" />
    <child
      link="right_mf_distal_link" />
    <axis
      xyz="0 1 0" />
    <limit
      lower="-1.23"
      upper="0.34"
      effort="50"
      velocity="1" />
    <mimic
      joint="right_mf_proximal_joint"
      multiplier="1"
      offset="0" />
  </joint>
  <link
    name="right_rf_proximal_link">
    <inertial>
      <origin
        xyz="-0.0159574731093167 -0.00508699297495175 -0.00788653991870907"
        rpy="0 0 0" />
      <mass
        value="0.00185229291559554" />
      <inertia
        ixx="8.87960405276781E-08"
        ixy="5.65163102187985E-09"
        ixz="-4.67021204809698E-08"
        iyy="1.8840957230307E-07"
        iyz="2.64384772912068E-09"
        izz="1.78055276074851E-07" />
    </inertial>
    <visual>
      <origin
        xyz="0 0 0"
        rpy="0 0 0" />
      <geometry>
        <mesh
          filename="package://meshes/right_rf_proximal_link.STL" />
      </geometry>
      <material
        name="">
        <color
          rgba="1 1 1 1" />
      </material>
    </visual>
    <collision>
      <origin
        xyz="0 0 0"
        rpy="0 0 0" />
      <geometry>
        <mesh
          filename="package://meshes/right_rf_proximal_link.STL" />
      </geometry>
    </collision>
  </link>
  <joint
    name="right_rf_proximal_joint"
    type="revolute">
    <origin
      xyz="-0.11258 0.0044858 0.014877"
      rpy="0 0 0" />
    <parent
      link="right_finger_base" />
    <child
      link="right_rf_proximal_link" />
    <axis
      xyz="0 1 0" />
    <limit
      lower="-1.23"
      upper="0.34"
      effort="50"
      velocity="1" />
  </joint>
  <link
    name="right_rf_distal_link">
    <inertial>
      <origin
        xyz="-0.0132013672271961 -0.00525332333018323 -0.0198360245917965"
        rpy="0 0 0" />
      <mass
        value="0.00411813438505178" />
      <inertia
        ixx="4.17567964091139E-07"
        ixy="8.83792091169937E-09"
        ixz="-2.39623187984756E-07"
        iyy="5.73527691798747E-07"
        iyz="1.35350117823584E-08"
        izz="2.3247215276718E-07" />
    </inertial>
    <visual>
      <origin
        xyz="0 0 0"
        rpy="0 0 0" />
      <geometry>
        <mesh
          filename="package://meshes/right_rf_distal_link.STL" />
      </geometry>
      <material
        name="">
        <color
          rgba="1 1 1 1" />
      </material>
    </visual>
    <collision>
      <origin
        xyz="0 0 0"
        rpy="0 0 0" />
      <geometry>
        <mesh
          filename="package://meshes/right_rf_distal_link.STL" />
      </geometry>
    </collision>
  </link>
  <joint
    name="right_rf_distal_joint"
    type="revolute">
    <origin
      xyz="-0.034749 0.0022617 -0.0088072"
      rpy="0 0 0" />
    <parent
      link="right_rf_proximal_link" />
    <child
      link="right_rf_distal_link" />
    <axis
      xyz="0 1 0" />
    <limit
      lower="-1.23"
      upper="0.34"
      effort="50"
      velocity="1" />
    <mimic
      joint="right_rf_proximal_joint"
      multiplier="1"
      offset="0" />
  </joint>
  <link
    name="right_th_link_1">
    <inertial>
      <origin
        xyz="0.00270659292318193 -0.00468066434180406 -0.00150236387262136"
        rpy="0 0 0" />
      <mass
        value="0.00211540567417261" />
      <inertia
        ixx="1.7524535629557E-07"
        ixy="-5.50208752881828E-08"
        ixz="-4.43809324813235E-09"
        iyy="1.42495552210395E-07"
        iyz="-2.42530529882035E-08"
        izz="1.70635228042348E-07" />
    </inertial>
    <visual>
      <origin
        xyz="0 0 0"
        rpy="0 0 0" />
      <geometry>
        <mesh
          filename="package://meshes/right_th_link_1.STL" />
      </geometry>
      <material
        name="">
        <color
          rgba="1 1 1 1" />
      </material>
    </visual>
    <collision>
      <origin
        xyz="0 0 0"
        rpy="0 0 0" />
      <geometry>
        <mesh
          filename="package://meshes/right_th_link_1.STL" />
      </geometry>
    </collision>
  </link>
  <joint
    name="right_th_joint_1"
    type="revolute">
    <origin
      xyz="-0.047896 -0.017816 -0.024618"
      rpy="0 0 0" />
    <parent
      link="right_finger_base" />
    <child
      link="right_th_link_1" />
    <axis
      xyz="1 0 0" />
    <limit
      lower="-1.571"
      upper="1.571"
      effort="50"
      velocity="1" />
  </joint>
  <link
    name="right_th_link_2">
    <inertial>
      <origin
        xyz="-0.00834633647940502 -0.00790061639194979 -0.0025612163065322"
        rpy="0 0 0" />
      <mass
        value="0.0066634254339578" />
      <inertia
        ixx="4.79987278390943E-07"
        ixy="2.81861563990933E-11"
        ixz="-4.91467867848404E-07"
        iyy="2.21316128962266E-06"
        iyz="-8.06170404221075E-11"
        izz="1.8860706671632E-06" />
    </inertial>
    <visual>
      <origin
        xyz="0 0 0"
        rpy="0 0 0" />
      <geometry>
        <mesh
          filename="package://meshes/right_th_link_2.STL" />
      </geometry>
      <material
        name="">
        <color
          rgba="1 1 1 1" />
      </material>
    </visual>
    <collision>
      <origin
        xyz="0 0 0"
        rpy="0 0 0" />
      <geometry>
        <mesh
          filename="package://meshes/right_th_link_2.STL" />
      </geometry>
    </collision>
  </link>
  <joint
    name="right_th_joint_2"
    type="revolute">
    <origin
      xyz="-0.013434 -0.026438 -0.014086"
      rpy="-1.5678 -0.21839 -0.00065226" />
    <parent
      link="right_th_link_1" />
    <child
      link="right_th_link_2" />
    <axis
      xyz="0 1 0" />
    <limit
      lower="-1.571"
      upper="1.571"
      effort="50"
      velocity="1" />
  </joint>
  <link
    name="right_th_link_3">
    <inertial>
      <origin
        xyz="-0.0213045047900868 -0.00350583745128136 0.000499870962888962"
        rpy="0 0 0" />
      <mass
        value="0.00503417004238488" />
      <inertia
        ixx="1.99445023591198E-07"
        ixy="1.59270498707835E-12"
        ixz="-5.81633739950867E-08"
        iyy="2.35221266539737E-07"
        iyz="-1.81601613420279E-12"
        izz="2.67880566003001E-07" />
    </inertial>
    <visual>
      <origin
        xyz="0 0 0"
        rpy="0 0 0" />
      <geometry>
        <mesh
          filename="package://meshes/right_th_link_3.STL" />
      </geometry>
      <material
        name="">
        <color
          rgba="1 1 1 1" />
      </material>
    </visual>
    <collision>
      <origin
        xyz="0 0 0"
        rpy="0 0 0" />
      <geometry>
        <mesh
          filename="package://meshes/right_th_link_3.STL" />
      </geometry>
    </collision>
  </link>
  <joint
    name="right_th_joint_3"
    type="revolute">
    <origin
      xyz="-0.028136 -0.0044434 -0.01595"
      rpy="0 0 0" />
    <parent
      link="right_th_link_2" />
    <child
      link="right_th_link_3" />
    <axis
      xyz="0 1 0" />
    <limit
      lower="-1.571"
      upper="1.571"
      effort="50"
      velocity="1" />
    <mimic
      joint="right_th_joint_2"
      multiplier="1"
      offset="0" />
  </joint>
  
  <link
    name="left_finger_base">
    <inertial>
      <origin
        xyz="-0.044221 0.0037711 -0.00014505"
        rpy="0 0 0" />
      <mass
        value="0.048053" />
      <inertia
        ixx="1.9591E-05"
        ixy="1.5274E-06"
        ixz="3.2051E-06"
        iyy="2.4369E-05"
        iyz="1.787E-06"
        izz="3.4767E-05" />
    </inertial>
    <visual>
      <origin
        xyz="0 0 0"
        rpy="0 0 0" />
      <geometry>
        <mesh
          filename="package://meshes/left_base_link.STL" />
      </geometry>
      <material
        name="">
        <color
          rgba="1 1 1 1" />
      </material>
    </visual>
    <collision>
      <origin
        xyz="0 0 0"
        rpy="0 0 0" />
      <geometry>
        <mesh
          filename="package://meshes/left_base_link.STL" />
      </geometry>
    </collision>
  </link>
  <link
    name="left_ff_proximal_link">
    <inertial>
      <origin
        xyz="-0.010083 -3.1677E-05 -0.003934"
        rpy="0 0 0" />
      <mass
        value="0.0026721" />
      <inertia
        ixx="8.6533E-08"
        ixy="9.266E-09"
        ixz="-2.6485E-08"
        iyy="2.3977E-07"
        iyz="2.3324E-09"
        izz="2.3864E-07" />
    </inertial>
    <visual>
      <origin
        xyz="0 0 0"
        rpy="0 0 0" />
      <geometry>
        <mesh
          filename="package://meshes/left_ff_proximal_link.STL" />
      </geometry>
      <material
        name="">
        <color
          rgba="1 1 1 1" />
      </material>
    </visual>
    <collision>
      <origin
        xyz="0 0 0"
        rpy="0 0 0" />
      <geometry>
        <mesh
          filename="package://meshes/left_ff_proximal_link.STL" />
      </geometry>
    </collision>
  </link>
  <joint
    name="left_ff_proximal_joint"
    type="revolute">
    <origin
      xyz="-0.11139 0.034646 0.0057572"
      rpy="0 0 0" />
    <parent
      link="left_finger_base" />
    <child
      link="left_ff_proximal_link" />
    <axis
      xyz="0 1 0" />
    <limit
      lower="-1.23"
      upper="0.34"
      effort="50"
      velocity="1" />
  </joint>
  <link
    name="left_ff_distal_link">
    <inertial>
      <origin
        xyz="-0.0159764300933163 -0.00259280667056406 -0.0171072715384723"
        rpy="0 0 0" />
      <mass
        value="0.00414310455795066" />
      <inertia
        ixx="3.31856379285574E-07"
        ixy="-3.63369298583383E-08"
        ixz="-2.54549308385868E-07"
        iyy="5.69787755851534E-07"
        iyz="-3.4409933988982E-08"
        izz="3.22702105638547E-07" />
    </inertial>
    <visual>
      <origin
        xyz="0 0 0"
        rpy="0 0 0" />
      <geometry>
        <mesh
          filename="package://meshes/left_ff_distal_link.STL" />
      </geometry>
      <material
        name="">
        <color
          rgba="1 1 1 1" />
      </material>
    </visual>
    <collision>
      <origin
        xyz="0 0 0"
        rpy="0 0 0" />
      <geometry>
        <mesh
          filename="package://meshes/left_ff_distal_link.STL" />
      </geometry>
    </collision>
  </link>
  <joint
    name="left_ff_distal_joint"
    type="revolute">
    <origin
      xyz="-0.034906 0.0015559 -0.0083266"
      rpy="0 0 0" />
    <parent
      link="left_ff_proximal_link" />
    <child
      link="left_ff_distal_link" />
    <axis
      xyz="0 1 0" />
    <limit
      lower="-1.23"
      upper="0.34"
      effort="50"
      velocity="1" />
    <mimic
      joint="left_ff_proximal_joint"
      multiplier="1"
      offset="0" />
  </joint>
  <link
    name="left_mf_proximal_link">
    <inertial>
      <origin
        xyz="-0.0018323 2.9063E-05 -0.0015292"
        rpy="0 0 0" />
      <mass
        value="0.0011447" />
      <inertia
        ixx="2.5618E-08"
        ixy="8.4633E-10"
        ixz="-1.4406E-08"
        iyy="9.9342E-08"
        iyz="-1.8295E-09"
        izz="8.2752E-08" />
    </inertial>
    <visual>
      <origin
        xyz="0 0 0"
        rpy="0 0 0" />
      <geometry>
        <mesh
          filename="package://meshes/left_mf_proximal_link.STL" />
      </geometry>
      <material
        name="">
        <color
          rgba="1 1 1 1" />
      </material>
    </visual>
    <collision>
      <origin
        xyz="0 0 0"
        rpy="0 0 0" />
      <geometry>
        <mesh
          filename="package://meshes/left_mf_proximal_link.STL" />
      </geometry>
    </collision>
  </link>
  <joint
    name="left_mf_proximal_joint"
    type="revolute">
    <origin
      xyz="-0.11472 0.015366 0.013131"
      rpy="0 0 0" />
    <parent
      link="left_finger_base" />
    <child
      link="left_mf_proximal_link" />
    <axis
      xyz="0 1 0" />
    <limit
      lower="-1.23"
      upper="0.34"
      effort="50"
      velocity="1" />
  </joint>
  <link
    name="left_mf_distal_link">
    <inertial>
      <origin
        xyz="-0.016184610615264 -0.00166564696518477 -0.0170276189282457"
        rpy="0 0 0" />
      <mass
        value="0.00414326280735001" />
      <inertia
        ixx="3.25171296632411E-07"
        ixy="-2.65419924731099E-08"
        ixz="-2.55947499270743E-07"
        iyy="5.71898737581529E-07"
        iyz="-2.50110369096119E-08"
        izz="3.27417746180198E-07" />
    </inertial>
    <visual>
      <origin
        xyz="0 0 0"
        rpy="0 0 0" />
      <geometry>
        <mesh
          filename="package://meshes/left_mf_distal_link.STL" />
      </geometry>
      <material
        name="">
        <color
          rgba="1 1 1 1" />
      </material>
    </visual>
    <collision>
      <origin
        xyz="0 0 0"
        rpy="0 0 0" />
      <geometry>
        <mesh
          filename="package://meshes/left_mf_distal_link.STL" />
      </geometry>
    </collision>
  </link>
  <joint
    name="left_mf_distal_joint"
    type="revolute">
    <origin
      xyz="-0.039577 2.2566E-05 -0.010735"
      rpy="0 0 0" />
    <parent
      link="left_mf_proximal_link" />
    <child
      link="left_mf_distal_link" />
    <axis
      xyz="0 1 0" />
    <limit
      lower="-1.23"
      upper="0.34"
      effort="50"
      velocity="1" />
    <mimic
      joint="left_mf_proximal_joint"
      multiplier="1"
      offset="0" />
  </joint>
  <link
    name="left_rf_proximal_link">
    <inertial>
      <origin
        xyz="-0.00994260395212963 -0.000976611309520058 -0.00413938026854722"
        rpy="0 0 0" />
      <mass
        value="0.00267212975682147" />
      <inertia
        ixx="8.77479790076545E-08"
        ixy="-8.42020738901584E-09"
        ixz="-2.73428272451802E-08"
        iyy="2.3972781897386E-07"
        iyz="-1.20953990548552E-09"
        izz="2.37469797509282E-07" />
    </inertial>
    <visual>
      <origin
        xyz="0 0 0"
        rpy="0 0 0" />
      <geometry>
        <mesh
          filename="package://meshes/left_rf_proximal_link.STL" />
      </geometry>
      <material
        name="">
        <color
          rgba="1 1 1 1" />
      </material>
    </visual>
    <collision>
      <origin
        xyz="0 0 0"
        rpy="0 0 0" />
      <geometry>
        <mesh
          filename="package://meshes/left_rf_proximal_link.STL" />
      </geometry>
    </collision>
  </link>
  <joint
    name="left_rf_proximal_joint"
    type="revolute">
    <origin
      xyz="-0.11258 -0.0044858 0.014877"
      rpy="0 0 0" />
    <parent
      link="left_finger_base" />
    <child
      link="left_rf_proximal_link" />
    <axis
      xyz="0 1 0" />
    <limit
      lower="-1.23"
      upper="0.34"
      effort="50"
      velocity="1" />
  </joint>
  <link
    name="left_rf_distal_link">
    <inertial>
      <origin
        xyz="-0.0147636035663776 -0.00300250428109043 -0.0180933356088557"
        rpy="0 0 0" />
      <mass
        value="0.00414222273952134" />
      <inertia
        ixx="3.65944609627885E-07"
        ixy="-4.01269264302946E-08"
        ixz="-2.50659653437648E-07"
        iyy="5.66675084381537E-07"
        iyz="-4.57769241627218E-08"
        izz="2.91199174933207E-07" />
    </inertial>
    <visual>
      <origin
        xyz="0 0 0"
        rpy="0 0 0" />
      <geometry>
        <mesh
          filename="package://meshes/left_rf_distal_link.STL" />
      </geometry>
      <material
        name="">
        <color
          rgba="1 1 1 1" />
      </material>
    </visual>
    <collision>
      <origin
        xyz="0 0 0"
        rpy="0 0 0" />
      <geometry>
        <mesh
          filename="package://meshes/left_rf_distal_link.STL" />
      </geometry>
    </collision>
  </link>
  <joint
    name="left_rf_distal_joint"
    type="revolute">
    <origin
      xyz="-0.034749 -0.0022617 -0.0088072"
      rpy="0 0 0" />
    <parent
      link="left_rf_proximal_link" />
    <child
      link="left_rf_distal_link" />
    <axis
      xyz="0 1 0" />
    <limit
      lower="-1.23"
      upper="0.34"
      effort="50"
      velocity="1" />
    <mimic
      joint="left_rf_proximal_joint"
      multiplier="1"
      offset="0" />
  </joint>
  <link
    name="left_lf_proximal_link">
    <inertial>
      <origin
        xyz="-0.00818709188997314 -0.000706293334690904 -0.00371474546876376"
        rpy="0 0 0" />
      <mass
        value="0.00246242716690493" />
      <inertia
        ixx="8.01816029752178E-08"
        ixy="-9.79441534624781E-09"
        ixz="-1.74883178144919E-08"
        iyy="1.88542552170038E-07"
        iyz="-1.4759274672654E-09"
        izz="1.88910686859292E-07" />
    </inertial>
    <visual>
      <origin
        xyz="0 0 0"
        rpy="0 0 0" />
      <geometry>
        <mesh
          filename="package://meshes/left_lf_proximal_link.STL" />
      </geometry>
      <material
        name="">
        <color
          rgba="1 1 1 1" />
      </material>
    </visual>
    <collision>
      <origin
        xyz="0 0 0"
        rpy="0 0 0" />
      <geometry>
        <mesh
          filename="package://meshes/left_lf_proximal_link.STL" />
      </geometry>
    </collision>
  </link>
  <joint
    name="left_lf_proximal_joint"
    type="revolute">
    <origin
      xyz="-0.10962 -0.025044 0.014795"
      rpy="0 0 0" />
    <parent
      link="left_finger_base" />
    <child
      link="left_lf_proximal_link" />
    <axis
      xyz="0 1 0" />
    <limit
      lower="-1.23"
      upper="0.34"
      effort="50"
      velocity="1" />
  </joint>
  <link
    name="left_lf_distal_link">
    <inertial>
      <origin
        xyz="-0.00977163702160722 -0.00143578665159429 -0.0131926510778022"
        rpy="0 0 0" />
      <mass
        value="0.00260955268765296" />
      <inertia
        ixx="1.12771893713449E-07"
        ixy="-6.42895918229416E-09"
        ixz="-5.86660356478732E-08"
        iyy="1.52225980270035E-07"
        iyz="-8.63068676151798E-09"
        izz="8.47032448458535E-08" />
    </inertial>
    <visual>
      <origin
        xyz="0 0 0"
        rpy="0 0 0" />
      <geometry>
        <mesh
          filename="package://meshes/left_lf_distal_link.STL" />
      </geometry>
      <material
        name="">
        <color
          rgba="1 1 1 1" />
      </material>
    </visual>
    <collision>
      <origin
        xyz="0 0 0"
        rpy="0 0 0" />
      <geometry>
        <mesh
          filename="package://meshes/left_lf_distal_link.STL" />
      </geometry>
    </collision>
  </link>
  <joint
    name="left_lf_distal_joint"
    type="revolute">
    <origin
      xyz="-0.030661 -0.0028404 -0.0084539"
      rpy="0 0 0" />
    <parent
      link="left_lf_proximal_link" />
    <child
      link="left_lf_distal_link" />
    <axis
      xyz="0 1 0" />
    <limit
      lower="-1.23"
      upper="0.34"
      effort="50"
      velocity="1" />
    <mimic
      joint="left_lf_proximal_joint"
      multiplier="1"
      offset="0" />
  </joint>
  <link
    name="left_th_proximal_link">
    <inertial>
      <origin
        xyz="0.00245605527295993 0.00432781869857057 -0.00242217457648963"
        rpy="0 0 0" />
      <mass
        value="0.00211540929576514" />
      <inertia
        ixx="1.77171011372901E-07"
        ixy="5.5204978225392E-08"
        ixz="-1.21341620430519E-08"
        iyy="1.4532633943915E-07"
        iyz="2.22260011074154E-08"
        izz="1.65881140312083E-07" />
    </inertial>
    <visual>
      <origin
        xyz="0 0 0"
        rpy="0 0 0" />
      <geometry>
        <mesh
          filename="package://meshes/left_th_proximal_link.STL" />
      </geometry>
      <material
        name="">
        <color
          rgba="1 1 1 1" />
      </material>
    </visual>
    <collision>
      <origin
        xyz="0 0 0"
        rpy="0 0 0" />
      <geometry>
        <mesh
          filename="package://meshes/left_th_proximal_link.STL" />
      </geometry>
    </collision>
  </link>
  <joint
    name="left_th_joint_1"
    type="revolute">
    <origin
      xyz="-0.047896 0.017816 -0.024618"
      rpy="0 0 0" />
    <parent
      link="left_finger_base" />
    <child
      link="left_th_proximal_link" />
    <axis
      xyz="1 0 0" />
    <limit
      lower="-1.571"
      upper="1.571"
      effort="50"
      velocity="1" />
  </joint>
  <link
    name="left_th_immediate_link">
    <inertial>
      <origin
        xyz="-0.00827891104685516 -0.00664973695486189 0.00277110396140376"
        rpy="0 0 0" />
      <mass
        value="0.00666243153716372" />
      <inertia
        ixx="5.05691442465771E-07"
        ixy="2.62183543539022E-11"
        ixz="5.26313627960527E-07"
        iyy="2.2129149290955E-06"
        iyz="-2.78492354336019E-11"
        izz="1.86000318173998E-06" />
    </inertial>
    <visual>
      <origin
        xyz="0 0 0"
        rpy="0 0 0" />
      <geometry>
        <mesh
          filename="package://meshes/left_th_immediate_link.STL" />
      </geometry>
      <material
        name="">
        <color
          rgba="0.752941176470588 0.752941176470588 0.752941176470588 1" />
      </material>
    </visual>
    <collision>
      <origin
        xyz="0 0 0"
        rpy="0 0 0" />
      <geometry>
        <mesh
          filename="package://meshes/left_th_immediate_link.STL" />
      </geometry>
    </collision>
  </link>
  <joint
    name="left_th_joint_2"
    type="revolute">
    <origin
      xyz="-0.014486 0.024977 -0.015016"
      rpy="-1.7169 -0.11331 0.016639" />
    <parent
      link="left_th_proximal_link" />
    <child
      link="left_th_immediate_link" />
    <axis
      xyz="0 1 0" />
    <limit
      lower="-1.571"
      upper="1.571"
      effort="50"
      velocity="1" />
  </joint>
  <link
    name="left_th_distal_link">
    <inertial>
      <origin
        xyz="-0.0213103251524451 9.41885523524678E-05 3.89005733728021E-05"
        rpy="0 0 0" />
      <mass
        value="0.00503405116330242" />
      <inertia
        ixx="2.02423567596468E-07"
        ixy="6.16199776059928E-12"
        ixz="5.98206952102564E-08"
        iyy="2.35220576917359E-07"
        iyz="-1.70913284120828E-12"
        izz="2.64892965153629E-07" />
    </inertial>
    <visual>
      <origin
        xyz="0 0 0"
        rpy="0 0 0" />
      <geometry>
        <mesh
          filename="package://meshes/left_th_distal_link.STL" />
      </geometry>
      <material
        name="">
        <color
          rgba="0.752941176470588 0.752941176470588 0.752941176470588 1" />
      </material>
    </visual>
    <collision>
      <origin
        xyz="0 0 0"
        rpy="0 0 0" />
      <geometry>
        <mesh
          filename="package://meshes/left_th_distal_link.STL" />
      </geometry>
    </collision>
  </link>
  <joint
    name="left_th_joint_3"
    type="revolute">
    <origin
      xyz="-0.027724 -0.0067934 0.016657"
      rpy="0 0 0" />
    <parent
      link="left_th_immediate_link" />
    <child
      link="left_th_distal_link" />
    <axis
      xyz="0 1 0" />
    <limit
      lower="-1.571"
      upper="1.571"
      effort="50"
      velocity="1" />
    <mimic
      joint="left_th_joint_2"
      multiplier="-1"
      offset="0" />
  </joint>
 
</robot>