<mujoco model="A2D">
  <compiler angle="radian" meshdir="./meshes/"/>

  <option>
    <flag contact="enable"/>  
  </option>
  
  <!-- 自定义碰撞排除 -->
  <contact>
    <exclude body1="base_car" body2="link_up_down_body"/>
    <exclude body1="base_car" body2="link_pitch_body"/>
  </contact>

  <asset>
    <mesh name="base_link" file="base_link.STL"/>
    <mesh name="link_up_down_body" file="link_up_down_body.STL"/>
    <mesh name="link_pitch_body" file="link_pitch_body.STL"/>
    <mesh name="link_yaw_head" file="link_yaw_head.STL"/>
    <mesh name="link_pitch_head" file="link_pitch_head.STL"/>
    <mesh name="base_link_l" file="base_link_l.STL"/>
    <mesh name="Link1_l" file="Link1_l.STL"/>
    <mesh name="Link2_l" file="Link2_l.STL"/>
    <mesh name="Link3_l" file="Link3_l.STL"/>
    <mesh name="Link4_l" file="Link4_l.STL"/>
    <mesh name="Link5_l" file="Link5_l.STL"/>
    <mesh name="Link6_l" file="Link6_l.STL"/>
    <mesh name="Link7_l" file="Link7_l.STL"/>
    <mesh name="base_link_r" file="base_link_r.STL"/>
    <mesh name="Link1_r" file="Link1_r.STL"/>
    <mesh name="Link2_r" file="Link2_r.STL"/>
    <mesh name="Link3_r" file="Link3_r.STL"/>
    <mesh name="Link4_r" file="Link4_r.STL"/>
    <mesh name="Link5_r" file="Link5_r.STL"/>
    <mesh name="Link6_r" file="Link6_r.STL"/>
    <mesh name="Link7_r" file="Link7_r.STL"/>
    <mesh name="right_base_link" file="right_base_link.STL"/>
    <mesh name="right_ff_proximal_link" file="right_ff_proximal_link.STL"/>
    <mesh name="right_ff_distal_link" file="right_ff_distal_link.STL"/>
    <mesh name="right_lf_proximal_link" file="right_lf_proximal_link.STL"/>
    <mesh name="right_lf_distal_link" file="right_lf_distal_link.STL"/>
    <mesh name="right_mf_proximal_link" file="right_mf_proximal_link.STL"/>
    <mesh name="right_mf_distal_link" file="right_mf_distal_link.STL"/>
    <mesh name="right_rf_proximal_link" file="right_rf_proximal_link.STL"/>
    <mesh name="right_rf_distal_link" file="right_rf_distal_link.STL"/>
    <mesh name="right_th_link_1" file="right_th_link_1.STL"/>
    <mesh name="right_th_link_2" file="right_th_link_2.STL"/>
    <mesh name="right_th_link_3" file="right_th_link_3.STL"/>
    <mesh name="left_base_link" file="left_base_link.STL"/>
    <mesh name="left_ff_proximal_link" file="left_ff_proximal_link.STL"/>
    <mesh name="left_ff_distal_link" file="left_ff_distal_link.STL"/>
    <mesh name="left_mf_proximal_link" file="left_mf_proximal_link.STL"/>
    <mesh name="left_mf_distal_link" file="left_mf_distal_link.STL"/>
    <mesh name="left_rf_proximal_link" file="left_rf_proximal_link.STL"/>
    <mesh name="left_rf_distal_link" file="left_rf_distal_link.STL"/>
    <mesh name="left_lf_proximal_link" file="left_lf_proximal_link.STL"/>
    <mesh name="left_lf_distal_link" file="left_lf_distal_link.STL"/>
    <mesh name="left_th_proximal_link" file="left_th_proximal_link.STL"/>
    <mesh name="left_th_immediate_link" file="left_th_immediate_link.STL"/>
    <mesh name="left_th_distal_link" file="left_th_distal_link.STL"/>
  </asset>

  <worldbody>
    <body name="base_car">
      <geom type="mesh" contype="0" conaffinity="0" group="1" density="0" rgba="0.752941 0.752941 0.752941 1" mesh="base_link"/>
      <geom type="mesh" rgba="0.752941 0.752941 0.752941 1" mesh="base_link"/>
      <!-- 0.6485 / 1.0 -->
      <body name="link_up_down_body" pos="0 0 0.6485">
        <inertial pos="0.0338352 -0.00248044 0.000838431" quat="0.70654 0.707661 -0.00251284 0.00337775" mass="3.26275" diaginertia="0.0128303 0.011172 0.00610409"/>
        <joint name="joint_lift_body" pos="0 0 0.4" axis="0 0 1" type="slide" range="0 0.5" actuatorfrcrange="-1000 1000"/>
        <geom type="mesh" contype="0" conaffinity="0" group="1" density="0" rgba="0.752941 0.752941 0.752941 1" mesh="link_up_down_body"/>
        <geom type="mesh" rgba="0.752941 0.752941 0.752941 1" mesh="link_up_down_body"/>
        <body name="link_pitch_body" pos="0.131 0 0" quat="0.499998 0.5 -0.5 0.500002">
          <inertial pos="0.241377 -0.000267221 -0.000883817" quat="0.512859 0.489922 0.511111 0.485508" mass="9.4053" diaginertia="0.15653 0.150662 0.0231066"/>
          <!-- <joint name="joint_body_pitch" pos="0 0 0" axis="0 0 -1" range="0 1.0472" actuatorfrcrange="-1000 1000"/> -->
          <geom pos="0 0 0" quat="1.32679e-06 1 0 0" type="mesh" contype="0" conaffinity="0" group="1" density="0" rgba="0.752941 0.752941 0.752941 1" mesh="link_pitch_body"/>
          <geom pos="0 0 0" quat="1.32679e-06 1 0 0" type="mesh" rgba="0.752941 0.752941 0.752941 1" mesh="link_pitch_body"/>
          <geom pos="0.441 0 0" quat="-0.499999 0.500002 -0.499999 0.499999" type="mesh" contype="0" conaffinity="0" group="1" density="0" rgba="0.752941 0.752941 0.752941 1" mesh="link_yaw_head"/>
          <geom pos="0.441 0 0" quat="-0.499999 0.500002 -0.499999 0.499999" type="mesh" rgba="0.752941 0.752941 0.752941 1" mesh="link_yaw_head"/>
          <geom pos="0.501065 -0.0502378 -2.20631e-07" quat="-0.707108 3.53554e-06 -1.65916e-06 0.707105" type="mesh" contype="0" conaffinity="0" group="1" density="0" rgba="0.752941 0.752941 0.752941 1" mesh="link_pitch_head"/>
          <geom pos="0.501065 -0.0502378 -2.20631e-07" quat="-0.707108 3.53554e-06 -1.65916e-06 0.707105" type="mesh" rgba="0.752941 0.752941 0.752941 1" mesh="link_pitch_head"/>
          <geom pos="0.305 0 -0.025" quat="-2.59734e-06 -0.707105 0.707108 2.59735e-06" type="mesh" contype="0" conaffinity="0" group="1" density="0" rgba="0.75294 0.75294 0.75294 1" mesh="base_link_l"/>
          <geom pos="0.305 0 -0.025" quat="-2.59734e-06 -0.707105 0.707108 2.59735e-06" type="mesh" rgba="0.75294 0.75294 0.75294 1" mesh="base_link_l"/>
          <geom pos="0.305 0 0.025" quat="0.707109 2.59735e-06 2.59734e-06 0.707105" type="mesh" contype="0" conaffinity="0" group="1" density="0" rgba="0.75294 0.75294 0.75294 1" mesh="base_link_r"/>
          <geom pos="0.305 0 0.025" quat="0.707109 2.59735e-06 2.59734e-06 0.707105" type="mesh" rgba="0.75294 0.75294 0.75294 1" mesh="base_link_r"/>
          <body name="Link1_l" pos="0.304999 5.41045e-12 -0.213" quat="0.707105 0 0 -0.707108">
            <inertial pos="-0.0014596 0.00049476 0.017089" quat="0.998871 0.00251503 -0.00488526 -0.0471962" mass="0.43694" diaginertia="0.000619607 0.000548463 0.00026659"/>
            <joint name="left_arm_joint1" pos="0 0 0" axis="0 0 -1" range="-3.14 3.14" actuatorfrcrange="-60 60"/>
            <geom type="mesh" contype="0" conaffinity="0" group="1" density="0" rgba="0.75294 0.75294 0.75294 1" mesh="Link1_l"/>
            <geom type="mesh" rgba="0.75294 0.75294 0.75294 1" mesh="Link1_l"/>
            <body name="Link2_l" quat="0.499998 -0.5 0.500002 -0.5">
              <inertial pos="-0.00043013 0.088101 -0.0065021" quat="0.475056 0.702719 -0.447305 0.283597" mass="0.31992" diaginertia="0.000336181 0.000329887 0.000200642"/>
              <joint name="left_arm_joint2" pos="0 0 0" axis="0 0 -1" range="-2.35619 2.35619" actuatorfrcrange="-60 60"/>
              <geom type="mesh" contype="0" conaffinity="0" group="1" density="0" rgba="0.75294 0.75294 0.75294 1" mesh="Link2_l"/>
              <geom type="mesh" rgba="0.75294 0.75294 0.75294 1" mesh="Link2_l"/>
              <body name="Link3_l" pos="0 0.305 0" quat="0.499998 0.5 0.5 -0.500002">
                <inertial pos="0.00022593 0.0010417 0.034985" quat="0.669198 0.00140477 -0.00266952 0.743078" mass="0.35545" diaginertia="0.000833637 0.000810307 0.000171256"/>
                <joint name="left_arm_joint3" pos="0 0 0" axis="0 0 -1" range="-3.14 3.14" actuatorfrcrange="-60 60"/>
                <geom type="mesh" contype="0" conaffinity="0" group="1" density="0" rgba="0.75294 0.75294 0.75294 1" mesh="Link3_l"/>
                <geom type="mesh" rgba="0.75294 0.75294 0.75294 1" mesh="Link3_l"/>
                <body name="Link4_l" quat="0.707105 -0.707108 0 0">
                  <inertial pos="2.1713e-06 0.071943 -0.0054645" quat="0.399193 0.583929 -0.583664 0.398759" mass="0.1848" diaginertia="0.000146656 0.00014344 8.1897e-05"/>
                  <joint name="left_arm_joint4" pos="0 0 0" axis="0 0 -1" range="-2.35619 2.35619" actuatorfrcrange="-60 60"/>
                  <geom type="mesh" contype="0" conaffinity="0" group="1" density="0" rgba="0.75294 0.75294 0.75294 1" mesh="Link4_l"/>
                  <geom type="mesh" rgba="0.75294 0.75294 0.75294 1" mesh="Link4_l"/>
                  <body name="Link5_l" pos="0 0.1975 0" quat="-2.59734e-06 -2.59735e-06 -0.707108 -0.707105">
                    <inertial pos="-7.6715e-07 -6.7798e-05 -0.012879" quat="0.707172 0.00145089 -0.00152478 0.707039" mass="0.1775" diaginertia="0.000137411 0.00012838 6.21007e-05"/>
                    <joint name="left_arm_joint5" pos="0 0 0" axis="0 0 1" range="-3.14 3.14" actuatorfrcrange="-30 30"/>
                    <geom type="mesh" contype="0" conaffinity="0" group="1" density="0" rgba="0.75294 0.75294 0.75294 1" mesh="Link5_l"/>
                    <geom type="mesh" rgba="0.75294 0.75294 0.75294 1" mesh="Link5_l"/>
                    <body name="Link6_l" quat="-2.59734e-06 2.59735e-06 -0.707108 0.707105">
                      <inertial pos="2.2696e-06 -0.10227 -0.0029117" quat="0.820281 0.571957 -0.00115947 0.00169569" mass="0.17825" diaginertia="0.00013761 0.00013558 7.33373e-05"/>
                      <joint name="left_arm_joint6" pos="0 0 0" axis="0 0 -1" range="-2.35619 2.35619" actuatorfrcrange="-30 30"/>
                      <geom type="mesh" contype="0" conaffinity="0" group="1" density="0" rgba="0.75294 0.75294 0.75294 1" mesh="Link6_l"/>
                      <geom type="mesh" rgba="0.75294 0.75294 0.75294 1" mesh="Link6_l"/>
                      <body name="Link7_l" pos="0 -0.181 0" quat="-2.59734e-06 2.59735e-06 0.707108 -0.707105">
                        <inertial pos="0.00150895 6.85905e-05 0.0097185" quat="0.634831 0.0404712 0.0161717 0.771421" mass="0.109633" diaginertia="0.000155916 0.000144682 4.78221e-05"/>
                        <joint name="left_arm_joint7" pos="0 0 0" axis="0 0 1" range="-6.28 6.28" actuatorfrcrange="-30 30"/>
                        <geom type="mesh" contype="0" conaffinity="0" group="1" density="0" rgba="0.75294 0.75294 0.75294 1" mesh="Link7_l"/>
                        <geom type="mesh" rgba="0.75294 0.75294 0.75294 1" mesh="Link7_l"/>
                        <geom pos="0 0 0" quat="0.499998 0.500002 0.5 -0.5" type="mesh" contype="0" conaffinity="0" group="1" density="0" rgba="1 1 1 1" mesh="left_base_link"/>
                        <geom pos="0 0 0" quat="0.499998 0.500002 0.5 -0.5" type="mesh" rgba="1 1 1 1" mesh="left_base_link"/>
                        <body name="left_ff_proximal_link" pos="0.034646 -0.00575774 0.11139" quat="0.499998 0.500002 0.5 -0.5">
                          <inertial pos="-0.010083 -3.1677e-05 -0.003934" quat="0.113882 0.642929 0.0571785 0.755251" mass="0.0026721" diaginertia="2.43311e-07 2.40152e-07 8.14801e-08"/>
                          <joint name="left_ff_proximal_joint" pos="0 0 0" axis="0 1 0" range="-1.23 0.34" actuatorfrcrange="-50 50"/>
                          <geom type="mesh" contype="0" conaffinity="0" group="1" density="0" rgba="1 1 1 1" mesh="left_ff_proximal_link"/>
                          <geom type="mesh" rgba="1 1 1 1" mesh="left_ff_proximal_link"/>
                          <body name="left_ff_distal_link" pos="-0.034906 0.0015559 -0.0083266">
                            <inertial pos="-0.0159764 -0.00259281 -0.0171073" quat="0.920212 -0.0899525 0.37023 -0.089717" mass="0.0041431" diaginertia="5.82302e-07 5.74338e-07 6.77072e-08"/>
                            <joint name="left_ff_distal_joint" pos="0 0 0" axis="0 1 0" range="-1.23 0.34" actuatorfrcrange="-50 50"/>
                            <geom type="mesh" contype="0" conaffinity="0" group="1" density="0" rgba="1 1 1 1" mesh="left_ff_distal_link"/>
                            <geom type="mesh" rgba="1 1 1 1" mesh="left_ff_distal_link"/>
                          </body>
                        </body>
                        <body name="left_mf_proximal_link" pos="0.015366 -0.0131315 0.11472" quat="0.499998 0.500002 0.5 -0.5">
                          <inertial pos="-0.0018323 2.9063e-05 -0.0015292" quat="0.5948 0.40683 0.467824 0.511706" mass="0.0011447" diaginertia="9.96342e-08 8.58888e-08 2.21891e-08"/>
                          <joint name="left_mf_proximal_joint" pos="0 0 0" axis="0 1 0" range="-1.23 0.34" actuatorfrcrange="-50 50"/>
                          <geom type="mesh" contype="0" conaffinity="0" group="1" density="0" rgba="1 1 1 1" mesh="left_mf_proximal_link"/>
                          <geom type="mesh" rgba="1 1 1 1" mesh="left_mf_proximal_link"/>
                          <body name="left_mf_distal_link" pos="-0.039577 2.2566e-05 -0.010735">
                            <inertial pos="-0.0161846 -0.00166565 -0.0170276" quat="0.0447006 0.380627 0.0575723 0.921852" mass="0.00414326" diaginertia="5.82372e-07 5.74407e-07 6.77086e-08"/>
                            <joint name="left_mf_distal_joint" pos="0 0 0" axis="0 1 0" range="-1.23 0.34" actuatorfrcrange="-50 50"/>
                            <geom type="mesh" contype="0" conaffinity="0" group="1" density="0" rgba="1 1 1 1" mesh="left_mf_distal_link"/>
                            <geom type="mesh" rgba="1 1 1 1" mesh="left_mf_distal_link"/>
                          </body>
                        </body>
                        <body name="left_rf_proximal_link" pos="-0.00448585 -0.0148774 0.11258" quat="0.499998 0.500002 0.5 -0.5">
                          <inertial pos="-0.0099426 -0.000976611 -0.00413938" quat="0.0313334 0.639762 0.0614469 0.765472" mass="0.00267213" diaginertia="2.42342e-07 2.40152e-07 8.24512e-08"/>
                          <joint name="left_rf_proximal_joint" pos="0 0 0" axis="0 1 0" range="-1.23 0.34" actuatorfrcrange="-50 50"/>
                          <geom type="mesh" contype="0" conaffinity="0" group="1" density="0" rgba="1 1 1 1" mesh="left_rf_proximal_link"/>
                          <geom type="mesh" rgba="1 1 1 1" mesh="left_rf_proximal_link"/>
                          <body name="left_rf_distal_link" pos="-0.034749 -0.0022617 -0.0088072">
                            <inertial pos="-0.0147636 -0.0030025 -0.0180933" quat="0.935856 -0.0678467 0.345684 -0.00851762" mass="0.00414222" diaginertia="5.82034e-07 5.74069e-07 6.77151e-08"/>
                            <joint name="left_rf_distal_joint" pos="0 0 0" axis="0 1 0" range="-1.23 0.34" actuatorfrcrange="-50 50"/>
                            <geom type="mesh" contype="0" conaffinity="0" group="1" density="0" rgba="1 1 1 1" mesh="left_rf_distal_link"/>
                            <geom type="mesh" rgba="1 1 1 1" mesh="left_rf_distal_link"/>
                          </body>
                        </body>
                        <body name="left_lf_proximal_link" pos="-0.0250441 -0.0147953 0.10962" quat="0.499998 0.500002 0.5 -0.5">
                          <inertial pos="-0.00818709 -0.000706293 -0.00371475" quat="-0.0185335 0.648885 0.0421688 0.759491" mass="0.00246243" diaginertia="1.91656e-07 1.89417e-07 7.65619e-08"/>
                          <joint name="left_lf_proximal_joint" pos="0 0 0" axis="0 1 0" range="-1.23 0.34" actuatorfrcrange="-50 50"/>
                          <geom type="mesh" contype="0" conaffinity="0" group="1" density="0" rgba="1 1 1 1" mesh="left_lf_proximal_link"/>
                          <geom type="mesh" rgba="1 1 1 1" mesh="left_lf_proximal_link"/>
                          <body name="left_lf_distal_link" pos="-0.030661 -0.0028404 -0.0084539">
                            <inertial pos="-0.00977164 -0.00143579 -0.0131927" quat="0.943052 -0.0357688 0.328372 0.0393201" mass="0.00260955" diaginertia="1.59074e-07 1.53219e-07 3.74083e-08"/>
                            <joint name="left_lf_distal_joint" pos="0 0 0" axis="0 1 0" range="-1.23 0.34" actuatorfrcrange="-50 50"/>
                            <geom type="mesh" contype="0" conaffinity="0" group="1" density="0" rgba="1 1 1 1" mesh="left_lf_distal_link"/>
                            <geom type="mesh" rgba="1 1 1 1" mesh="left_lf_distal_link"/>
                          </body>
                        </body>
                        <body name="left_th_proximal_link" pos="0.0178161 0.0246178 0.0478961" quat="0.499998 0.500002 0.5 -0.5">
                          <inertial pos="0.00245606 0.00432782 -0.00242217" quat="0.764762 0.555374 0.157619 0.286103" mass="0.00211541" diaginertia="2.18986e-07 1.74461e-07 9.49314e-08"/>
                          <joint name="left_th_joint_1" pos="0 0 0" axis="1 0 0" range="-1.571 1.571" actuatorfrcrange="-50 50"/>
                          <geom type="mesh" contype="0" conaffinity="0" group="1" density="0" rgba="1 1 1 1" mesh="left_th_proximal_link"/>
                          <geom type="mesh" rgba="1 1 1 1" mesh="left_th_proximal_link"/>
                          <body name="left_th_immediate_link" pos="-0.014486 0.024977 -0.015016" quat="0.652897 -0.755282 -0.0432955 -0.0374249">
                            <inertial pos="-0.00827891 -0.00664974 0.0027711" quat="0.411007 0.575382 0.575434 0.410955" mass="0.00666243" diaginertia="2.21291e-06 2.04049e-06 3.25207e-07"/>
                            <joint name="left_th_joint_2" pos="0 0 0" axis="0 1 0" range="-1.571 1.571" actuatorfrcrange="-50 50"/>
                            <geom type="mesh" contype="0" conaffinity="0" group="1" density="0" rgba="0.752941 0.752941 0.752941 1" mesh="left_th_immediate_link"/>
                            <geom type="mesh" rgba="0.752941 0.752941 0.752941 1" mesh="left_th_immediate_link"/>
                            <body name="left_th_distal_link" pos="-0.027724 -0.0067934 0.016657">
                              <inertial pos="-0.0213103 9.41886e-05 3.89006e-05" quat="4.52847e-05 0.871276 -1.04339e-05 0.490793" mass="0.00503405" diaginertia="3.01143e-07 2.35221e-07 1.66174e-07"/>
                              <joint name="left_th_joint_3" pos="0 0 0" axis="0 1 0" range="-1.571 1.571" actuatorfrcrange="-50 50"/>
                              <geom type="mesh" contype="0" conaffinity="0" group="1" density="0" rgba="0.752941 0.752941 0.752941 1" mesh="left_th_distal_link"/>
                              <geom type="mesh" rgba="0.752941 0.752941 0.752941 1" mesh="left_th_distal_link"/>
                            </body>
                          </body>
                        </body>
                      </body>
                    </body>
                  </body>
                </body>
              </body>
            </body>
          </body>
          <body name="Link1_r" pos="0.305001 -7.24292e-12 0.213" quat="-3.44619e-12 -0.707109 -0.707105 3.44616e-12">
            <inertial pos="0.0013193 0.00016098 0.018211" quat="0.999757 0.00181899 0.00876807 0.020151" mass="0.48414" diaginertia="0.000726233 0.000666797 0.000284199"/>
            <joint name="right_arm_joint1" pos="0 0 0" axis="0 0 -1" range="-3.14 3.14" actuatorfrcrange="-60 60"/>
            <geom type="mesh" contype="0" conaffinity="0" group="1" density="0" rgba="0.75294 0.75294 0.75294 1" mesh="Link1_r"/>
            <geom type="mesh" rgba="0.75294 0.75294 0.75294 1" mesh="Link1_r"/>
            <body name="Link2_r" quat="0.499998 0.5 -0.500002 -0.5">
              <inertial pos="0.00012037 -0.088102 -0.0062668" quat="0.781769 0.524782 0.184639 -0.281689" mass="0.31993" diaginertia="0.000333302 0.000331349 0.000202089"/>
              <joint name="right_arm_joint2" pos="0 0 0" axis="0 0 -1" range="-2.35619 2.35619" actuatorfrcrange="-60 60"/>
              <geom type="mesh" contype="0" conaffinity="0" group="1" density="0" rgba="0.75294 0.75294 0.75294 1" mesh="Link2_r"/>
              <geom type="mesh" rgba="0.75294 0.75294 0.75294 1" mesh="Link2_r"/>
              <body name="Link3_r" pos="0 -0.305 0" quat="0.499998 0.5 0.5 -0.500002">
                <inertial pos="-3.7545e-06 -0.00012549 -0.035846" quat="1 0.000235331 -1.05745e-05 -1.21063e-06" mass="0.34932" diaginertia="0.00084957 0.00082652 0.00021145"/>
                <joint name="right_arm_joint3" pos="0 0 0" axis="0 0 1" range="-3.14 3.14" actuatorfrcrange="-60 60"/>
                <geom type="mesh" contype="0" conaffinity="0" group="1" density="0" rgba="0.75294 0.75294 0.75294 1" mesh="Link3_r"/>
                <geom type="mesh" rgba="0.75294 0.75294 0.75294 1" mesh="Link3_r"/>
                <body name="Link4_r" quat="-2.59734e-06 -2.59735e-06 -0.707108 -0.707105">
                  <inertial pos="1.9102e-06 0.071943 -0.0054646" quat="0.399239 0.584027 -0.58358 0.398692" mass="0.1848" diaginertia="0.000146647 0.00014343 8.18954e-05"/>
                  <joint name="right_arm_joint4" pos="0 0 0" axis="0 0 -1" range="-2.35619 2.35619" actuatorfrcrange="-60 60"/>
                  <geom type="mesh" contype="0" conaffinity="0" group="1" density="0" rgba="0.75294 0.75294 0.75294 1" mesh="Link4_r"/>
                  <geom type="mesh" rgba="0.75294 0.75294 0.75294 1" mesh="Link4_r"/>
                  <body name="Link5_r" pos="0 0.1975 0" quat="-2.59734e-06 -2.59735e-06 -0.707108 -0.707105">
                    <inertial pos="4.0146e-06 -6.7798e-05 -0.012877" quat="0.70697 0.00144025 -0.00151521 0.707241" mass="0.1775" diaginertia="0.000137411 0.00012838 6.21007e-05"/>
                    <joint name="right_arm_joint5" pos="0 0 0" axis="0 0 1" range="-3.14 3.14" actuatorfrcrange="-30 30"/>
                    <geom type="mesh" contype="0" conaffinity="0" group="1" density="0" rgba="0.75294 0.75294 0.75294 1" mesh="Link5_r"/>
                    <geom type="mesh" rgba="0.75294 0.75294 0.75294 1" mesh="Link5_r"/>
                    <body name="Link6_r" quat="-2.59734e-06 2.59735e-06 -0.707108 0.707105">
                      <inertial pos="-2.4946e-06 -0.10227 -0.0029098" quat="0.820289 0.571947 -0.000938508 0.00131279" mass="0.17825" diaginertia="0.00013761 0.000135581 7.3336e-05"/>
                      <joint name="right_arm_joint6" pos="0 0 0" axis="0 0 -1" range="-2.35619 2.35619" actuatorfrcrange="-30 30"/>
                      <geom type="mesh" contype="0" conaffinity="0" group="1" density="0" rgba="0.75294 0.75294 0.75294 1" mesh="Link6_r"/>
                      <geom type="mesh" rgba="0.75294 0.75294 0.75294 1" mesh="Link6_r"/>
                      <body name="Link7_r" pos="0 -0.181 0" quat="-2.59734e-06 2.59735e-06 -0.707108 0.707105">
                        <inertial pos="-0.000485252 -0.00355471 -0.0216295" quat="0.619152 0.285463 0.684474 0.25818" mass="0.102622" diaginertia="4.99099e-05 4.52699e-05 3.93351e-05"/>
                        <joint name="right_arm_joint7" pos="0 0 0" axis="0 0 1" range="-3.14 3.14" actuatorfrcrange="-30 30"/>
                        <geom type="mesh" contype="0" conaffinity="0" group="1" density="0" rgba="0.75294 0.75294 0.75294 1" mesh="Link7_r"/>
                        <geom type="mesh" rgba="0.75294 0.75294 0.75294 1" mesh="Link7_r"/>
                        <geom pos="0 0 0" quat="0.499998 0.500002 0.5 -0.5" type="mesh" contype="0" conaffinity="0" group="1" density="0" rgba="1 1 1 1" mesh="right_base_link"/>
                        <geom pos="0 0 0" quat="0.499998 0.500002 0.5 -0.5" type="mesh" rgba="1 1 1 1" mesh="right_base_link"/>
                        <body name="right_ff_proximal_link" pos="-0.034646 -0.00575748 0.11139" quat="0.499998 0.500002 0.5 -0.5">
                          <inertial pos="-0.015386 -0.0066062 -0.0079647" quat="-0.0587925 0.563369 -0.0126267 0.824014" mass="0.0018523" diaginertia="1.98152e-07 1.88732e-07 6.83787e-08"/>
                          <joint name="right_ff_proximal_joint" pos="0 0 0" axis="0 1 0" range="-1.23 0.34" actuatorfrcrange="-50 50"/>
                          <geom type="mesh" contype="0" conaffinity="0" group="1" density="0" rgba="1 1 1 1" mesh="right_ff_proximal_link"/>
                          <geom type="mesh" rgba="1 1 1 1" mesh="right_ff_proximal_link"/>
                          <body name="right_ff_distal_link" pos="-0.034906 -0.0015559 -0.0083266">
                            <inertial pos="-0.0136745 -0.00546356 -0.019458" quat="0.94319 0.0276983 0.326752 0.0534584" mass="0.00411871" diaginertia="5.82116e-07 5.74231e-07 6.76238e-08"/>
                            <joint name="right_ff_distal_joint" pos="0 0 0" axis="0 1 0" range="-1.23 0.34" actuatorfrcrange="-50 50"/>
                            <geom type="mesh" contype="0" conaffinity="0" group="1" density="0" rgba="1 1 1 1" mesh="right_ff_distal_link"/>
                            <geom type="mesh" rgba="1 1 1 1" mesh="right_ff_distal_link"/>
                          </body>
                        </body>
                        <body name="right_lf_proximal_link" pos="0.0250439 -0.0147955 0.10962" quat="0.499998 0.500002 0.5 -0.5">
                          <inertial pos="-0.0146093 -0.00555089 -0.00670762" quat="0.0732449 0.533445 0.00535083 0.842641" mass="0.00164259" diaginertia="1.47711e-07 1.37975e-07 6.22251e-08"/>
                          <joint name="right_lf_proximal_joint" pos="0 0 0" axis="0 1 0" range="-1.23 0.34" actuatorfrcrange="-50 50"/>
                          <geom type="mesh" contype="0" conaffinity="0" group="1" density="0" rgba="1 1 1 1" mesh="right_lf_proximal_link"/>
                          <geom type="mesh" rgba="1 1 1 1" mesh="right_lf_proximal_link"/>
                          <body name="right_lf_distal_link" pos="-0.030661 0.0028404 -0.0084539">
                            <inertial pos="-0.00921516 -0.00657934 -0.013706" quat="0.957981 -0.0219706 0.275902 -0.0752809" mass="0.00258549" diaginertia="1.58971e-07 1.53191e-07 3.73147e-08"/>
                            <joint name="right_lf_distal_joint" pos="0 0 0" axis="0 1 0" range="-1.23 0.34" actuatorfrcrange="-50 50"/>
                            <geom type="mesh" contype="0" conaffinity="0" group="1" density="0" rgba="1 1 1 1" mesh="right_lf_distal_link"/>
                            <geom type="mesh" rgba="1 1 1 1" mesh="right_lf_distal_link"/>
                          </body>
                        </body>
                        <body name="right_mf_proximal_link" pos="-0.015366 -0.0131314 0.11472" quat="0.499998 0.500002 0.5 -0.5">
                          <inertial pos="-0.0177059 -0.00685749 -0.0094957" quat="-0.00558931 0.543821 0.00357762 0.839175" mass="0.00222073" diaginertia="2.89752e-07 2.82329e-07 8.41293e-08"/>
                          <joint name="right_mf_proximal_joint" pos="0 0 0" axis="0 1 0" range="-1.23 0.34" actuatorfrcrange="-50 50"/>
                          <geom type="mesh" contype="0" conaffinity="0" group="1" density="0" rgba="1 1 1 1" mesh="right_mf_proximal_link"/>
                          <geom type="mesh" rgba="1 1 1 1" mesh="right_mf_proximal_link"/>
                          <body name="right_mf_distal_link" pos="-0.039577 -2.2566e-05 -0.010735">
                            <inertial pos="-0.014345 -0.00680159 -0.018741" quat="0.942389 -0.00222821 0.334454 0.00621004" mass="0.00411872" diaginertia="5.82105e-07 5.74217e-07 6.76193e-08"/>
                            <joint name="right_mf_distal_joint" pos="0 0 0" axis="0 1 0" range="-1.23 0.34" actuatorfrcrange="-50 50"/>
                            <geom type="mesh" contype="0" conaffinity="0" group="1" density="0" rgba="1 1 1 1" mesh="right_mf_distal_link"/>
                            <geom type="mesh" rgba="1 1 1 1" mesh="right_mf_distal_link"/>
                          </body>
                        </body>
                        <body name="right_rf_proximal_link" pos="0.00448575 -0.0148774 0.11258" quat="0.499998 0.500002 0.5 -0.5">
                          <inertial pos="-0.0159575 -0.00508699 -0.00788654" quat="0.0236791 0.550833 -0.0154941 0.834136" mass="0.00185229" diaginertia="1.98028e-07 1.88729e-07 6.85034e-08"/>
                          <joint name="right_rf_proximal_joint" pos="0 0 0" axis="0 1 0" range="-1.23 0.34" actuatorfrcrange="-50 50"/>
                          <geom type="mesh" contype="0" conaffinity="0" group="1" density="0" rgba="1 1 1 1" mesh="right_rf_proximal_link"/>
                          <geom type="mesh" rgba="1 1 1 1" mesh="right_rf_proximal_link"/>
                          <body name="right_rf_distal_link" pos="-0.034749 0.0022617 -0.0088072">
                            <inertial pos="-0.0132014 -0.00525332 -0.019836" quat="0.954686 0.00836685 0.296277 -0.0269207" mass="0.00411813" diaginertia="5.81911e-07 5.74027e-07 6.76295e-08"/>
                            <joint name="right_rf_distal_joint" pos="0 0 0" axis="0 1 0" range="-1.23 0.34" actuatorfrcrange="-50 50"/>
                            <geom type="mesh" contype="0" conaffinity="0" group="1" density="0" rgba="1 1 1 1" mesh="right_rf_distal_link"/>
                            <geom type="mesh" rgba="1 1 1 1" mesh="right_rf_distal_link"/>
                          </body>
                        </body>
                        <body name="right_th_link_1" pos="-0.0178159 0.0246179 0.0478961" quat="0.499998 0.500002 0.5 -0.5">
                          <inertial pos="0.00270659 -0.00468066 -0.00150236" quat="0.588818 0.726967 -0.336543 -0.107478" mass="0.00211541" diaginertia="2.18985e-07 1.74461e-07 9.49307e-08"/>
                          <joint name="right_th_joint_1" pos="0 0 0" axis="1 0 0" range="-1.571 1.571" actuatorfrcrange="-50 50"/>
                          <geom type="mesh" contype="0" conaffinity="0" group="1" density="0" rgba="1 1 1 1" mesh="right_th_link_1"/>
                          <geom type="mesh" rgba="1 1 1 1" mesh="right_th_link_1"/>
                          <body name="right_th_link_2" pos="-0.013434 -0.026438 -0.014086" quat="0.703922 -0.701867 -0.0769456 -0.0771732">
                            <inertial pos="-0.00834634 -0.00790062 -0.00256122" quat="0.570303 0.418126 0.418332 0.57002" mass="0.00666343" diaginertia="2.21316e-06 2.04082e-06 3.25236e-07"/>
                            <joint name="right_th_joint_2" pos="0 0 0" axis="0 1 0" range="-1.571 1.571" actuatorfrcrange="-50 50"/>
                            <geom type="mesh" contype="0" conaffinity="0" group="1" density="0" rgba="1 1 1 1" mesh="right_th_link_2"/>
                            <geom type="mesh" rgba="1 1 1 1" mesh="right_th_link_2"/>
                            <body name="right_th_link_3" pos="-0.028136 -0.0044434 -0.01595">
                              <inertial pos="-0.0213045 -0.00350584 0.000499871" quat="-1.55298e-05 0.501769 -9.00852e-06 0.865002" mass="0.00503417" diaginertia="3.01145e-07 2.35221e-07 1.66181e-07"/>
                              <joint name="right_th_joint_3" pos="0 0 0" axis="0 1 0" range="-1.571 1.571" actuatorfrcrange="-50 50"/>
                              <geom type="mesh" contype="0" conaffinity="0" group="1" density="0" rgba="1 1 1 1" mesh="right_th_link_3"/>
                              <geom type="mesh" rgba="1 1 1 1" mesh="right_th_link_3"/>
                            </body>
                          </body>
                        </body>
                      </body>
                    </body>
                  </body>
                </body>
              </body>
            </body>
          </body>
        </body>
      </body>
    </body>
  </worldbody>

  <!-- actuator -->
  <actuator>
    <!-- Main body joints -->
    <motor name="actuator_lift_body" joint="joint_lift_body" ctrlrange="-30 30"/>
    <!-- <motor name="actuator_body_pitch" joint="joint_body_pitch" ctrlrange="-50 50"/> -->

    <!-- Left arm joints -->
    <motor name="actuator_left_arm_joint1" joint="left_arm_joint1" ctrlrange="-30 30"/>
    <motor name="actuator_left_arm_joint2" joint="left_arm_joint2" ctrlrange="-30 30"/>
    <motor name="actuator_left_arm_joint3" joint="left_arm_joint3" ctrlrange="-30 30"/>
    <motor name="actuator_left_arm_joint4" joint="left_arm_joint4" ctrlrange="-30 30"/>
    <motor name="actuator_left_arm_joint5" joint="left_arm_joint5" ctrlrange="-30 30"/>
    <motor name="actuator_left_arm_joint6" joint="left_arm_joint6" ctrlrange="-30 30"/>
    <motor name="actuator_left_arm_joint7" joint="left_arm_joint7" ctrlrange="-3.5 3.5"/>

    <!-- Left hand finger joints -->
    <motor name="actuator_left_ff_proximal" joint="left_ff_proximal_joint" ctrlrange="-4 4"/>
    <motor name="actuator_left_ff_distal" joint="left_ff_distal_joint" ctrlrange="-4 4"/>
    <motor name="actuator_left_mf_proximal" joint="left_mf_proximal_joint" ctrlrange="-4 4"/>
    <motor name="actuator_left_mf_distal" joint="left_mf_distal_joint" ctrlrange="-4 4"/>
    <motor name="actuator_left_rf_proximal" joint="left_rf_proximal_joint" ctrlrange="-4 4"/>
    <motor name="actuator_left_rf_distal" joint="left_rf_distal_joint" ctrlrange="-4 4"/>
    <motor name="actuator_left_lf_proximal" joint="left_lf_proximal_joint" ctrlrange="-4 4"/>
    <motor name="actuator_left_lf_distal" joint="left_lf_distal_joint" ctrlrange="-4 4"/>
    <motor name="actuator_left_th_1" joint="left_th_joint_1" ctrlrange="-4 4"/>
    <motor name="actuator_left_th_2" joint="left_th_joint_2" ctrlrange="-4 4"/>
    <motor name="actuator_left_th_3" joint="left_th_joint_3" ctrlrange="-4 4"/>

    <!-- Right arm joints -->
    <motor name="actuator_right_arm_joint1" joint="right_arm_joint1" ctrlrange="-30 30"/>
    <motor name="actuator_right_arm_joint2" joint="right_arm_joint2" ctrlrange="-30 30"/>
    <motor name="actuator_right_arm_joint3" joint="right_arm_joint3" ctrlrange="-30 30"/>
    <motor name="actuator_right_arm_joint4" joint="right_arm_joint4" ctrlrange="-30 30"/>
    <motor name="actuator_right_arm_joint5" joint="right_arm_joint5" ctrlrange="-30 30"/>
    <motor name="actuator_right_arm_joint6" joint="right_arm_joint6" ctrlrange="-30 30"/>
    <motor name="actuator_right_arm_joint7" joint="right_arm_joint7" ctrlrange="-3.5 3.5"/>

    <!-- Right hand finger joints -->
    <motor name="actuator_right_ff_proximal" joint="right_ff_proximal_joint" ctrlrange="-4 4"/>
    <motor name="actuator_right_ff_distal" joint="right_ff_distal_joint" ctrlrange="-4 4"/>
    <motor name="actuator_right_lf_proximal" joint="right_lf_proximal_joint" ctrlrange="-4 4"/>
    <motor name="actuator_right_lf_distal" joint="right_lf_distal_joint" ctrlrange="-4 4"/>
    <motor name="actuator_right_mf_proximal" joint="right_mf_proximal_joint" ctrlrange="-4 4"/>
    <motor name="actuator_right_mf_distal" joint="right_mf_distal_joint" ctrlrange="-4 4"/>
    <motor name="actuator_right_rf_proximal" joint="right_rf_proximal_joint" ctrlrange="-4 4"/>
    <motor name="actuator_right_rf_distal" joint="right_rf_distal_joint" ctrlrange="-4 4"/>
    <motor name="actuator_right_th_1" joint="right_th_joint_1" ctrlrange="-4 4"/>
    <motor name="actuator_right_th_2" joint="right_th_joint_2" ctrlrange="-4 4"/>
    <motor name="actuator_right_th_3" joint="right_th_joint_3" ctrlrange="-4 4"/>
  </actuator>

</mujoco>
